Workbook

Sheet Summary
E2: Jan | F2: Feb | G2: Mar | H2: Apr | I2: May | J2: Jun | K2: July | L2: Aug | M2: Sep | N2: Oct | O2: Nov | P2: Dec | Q2: Wages | R2: Fed Tax Withheld | S2: soc sec wages | T2: soc sec tax withheld | U2: medicare wages & tips | V2: medicare taxes withheld | W2: soc sec tips | X2: 2016
C3: Total Credits | E3: =Jan!I4 -> 20 | F3: =Feb!I4 -> 1300 | G3: =Mar!J4 -> 2800 | H3: =April!J4 -> 6100 | I3: =May!J4 -> 233.33 | J3: =June!J4 -> 2203.19 | K3: =July!J4 -> 3483.94 | X3: =SUM(E3:P3) -> 16140.46
C5: Total Debits | E5: =Jan!J5 -> 591.98 | F5: =Feb!J5 -> 1236.98 | G5: =Mar!L5 -> 1600 | H5: =April!K5 -> 5211.56 | I5: =May!L5 -> 1983.63 | J5: =June!L5 -> 1729.89 | K5: =July!L5 -> 2989.47 | X5: =SUM(E5:P5) -> 15343.51
C7: Net Income | E7: =Jan!I7 -> -571.98 | F7: =Feb!I7 -> 63.02 | G7: =Mar!J7 -> 1200 | H7: =April!J7 -> 888.44 | I7: =May!J7 -> -1750.3 | J7: =J3-J5 -> 473.3 | K7: =July!J7 -> 494.47 | X7: =SUM(E7:P7) -> 796.95
C8: Total Revenue | D8: =SUM(E8:P8) -> 26381.74 | E8: 10366.82 | F8: 9087.3 | G8: 4168.17 | H8: 2759.45
C9: Total Expenses | D9: =SUM(D11:D48) -> 36272.685 | E9: =SUM(E11:E42) -> 8520.72 | F9: =SUM(F11:F42) -> 7824.76 | G9: =SUM(G11:G42) -> 3929.92 | H9: =SUM(H11:H42) -> 7031.07 | I9: =SUM(I11:I42) -> 705.07 | J9: =SUM(J11:J42) -> 199.84 | K9: =SUM(K11:K42) -> 701.08 | L9: =SUM(L11:L42) -> 282 | ... P9: =SUM(P11:P42) -> 1077
C11: RENT | D11: =SUM(E11:P11) -> 7800 | E11: 3900 | H11: 3900
C12: ELECTRICITY | D12: =SUM(E12:P12) -> 0
C13: WASTE | D13: =SUM(E13:P13) -> 0
C14: EQUIPMENT LEASING | D14: =SUM(E14:P14) -> 2358.25 | E14: 474.05 | F14: 471.05 | G14: 471.05 | H14: 471.05 | I14: 471.05
D15: =SUM(E15:P15) -> 0
C16: WA DOR | D16: =SUM(E16:P16) -> 9325.49 | E16: 1942.18 | F16: 2344.46 | G16: 385.9 | K16: 341.24 | N16: 3311.71 | P16: 1000
C17: 2017 Excise | D17: =SUM(E17:P17) -> 3056.02 | E17: 1303.2 | F17: 1044.17 | G17: 432.3 | H17: 276.35
C18: Garnishment Fee | D18: =SUM(E18:P18) -> 625 | E18: 125 | F18: 125 | G18: 125 | K18: 125 | L18: 125
D19: =SUM(E19:P19) -> 0
C20: Food Inventory | D20: =SUM(E20:P20) -> 371.78 | E20: =267.16+33.03 -> 300.19 | G20: 21.01 | H20: 50.58
C21: Supplies | D21: =SUM(E21:P21) -> 115.38 | E21: =32.84+61.78 -> 94.62 | F21: 20.76
C22: STATIONARIES | D22: =SUM(E22:P22) -> 0
C23: PAYROLL | D23: =SUM(E23:P23) -> 0
C24: Wages | D24: 912.6 | M24: =768.5+370 -> 1138.5
C25: SS withheld by ADP | D25: 56.59
C26: Medicare Tax Withheld by ADP | D26: 13.23
C27: Fed Tax Withheld | D27: 1.98
C28: SERVICES | D28: =SUM(E28:P28) -> 7131 | F28: =500+400+400+100+500+600+85+386 -> 2971 | G28: =70+100+205+1100+610 -> 2085 | H28: 2075
C29: ADP Fees | D29: =SUM(E29:P29) -> 464.27 | F29: =45.57+25+139.5 -> 210.07 | G29: 42.84 | H29: 42.84 | I29: 10 | J29: 52.84 | K29: =10+42.84 -> 52.84 | L29: 10 | M29: 42.84
C30: Bank Fees | D30: =SUM(E30:P30) -> 1408.5 | E30: =70+10 -> 80 | F30: =385+70+10 -> 465 | G30: =175+7 -> 182 | H30: =35+7 -> 42 | I30: =35+9.5 -> 44.5 | J30: =140+7 -> 147 | K30: =175+7 -> 182 | L30: =140+7 -> 147 | M30: =35 -> 35 | N30: 0 | O30: 7 | P30: =70+7 -> 77
C33: LAUNDRY | D33: =SUM(E33:P33) -> 0
D34: =SUM(E34:P34) -> 0
D35: =SUM(E35:P35) -> 0
C36: WEB HOSTING | D36: 360
C37: Comcast Business BROADBAND | D37: =SUM(E37:P37) -> 884.19 | E37: 173.35 | F37: 173.25 | G37: 184.82 | H37: 173.25 | I37: 179.52
C38: PHONE | D38: 420
B39: 0.5 | C39: CELLULAR | D39: =SUM(E39:P39)*B39 -> 64.065 | E39: 128.13
C40: Digital Ads | D40: =SUM(E40:P40) -> 0
D41: =SUM(E41:P41) -> 0
C44: Asbestos | D44: 750
C45: Flooring Cement
C46: Paint | D46: 154.34
C47: Ceiling Speakers
C48: Equipment Purchase
...

Sheet Jan
G4: Total Credits | I4: =SUM(I13:I20) -> 20
G5: Total Debits | J5: =SUM(J13:J23) -> 591.98
G7: Net Income | I7: =I4-J5 -> -571.98
G13: Other Deposts/Additions | I13: 20
G14: ACH Payments | J14: 5
G15: ACH Deposits
G16: Manual Checks
G17: Card Withdrawals
G18: Other Withdrawals | J18: 7
G21: Payee | H21: Description | L21: RENT | M21: Electricity | N21: Equipment | O21: Inventory | P21: Promissory | Q21: Broadband | R21: Labor | T21: Fees | U21: Construction
E22: Check#1016 | F22: 42374 | G22: Kris Robbins | H22: Promissory Note | J22: 579.98 | O22: 579.98
F29: 42381 | G29: STATE OF WA | H29: LIQ PERMIT | J29: 233.33 | T29: 233.33

Sheet Feb
G4: Total Credits | I4: =SUM(I12:I18) -> 1300
G5: Total Debits | J5: =SUM(J12:J23) -> 1236.98
G7: Net Income | I7: =I4-J5 -> 63.02
G12: Deposits/Additions | I12: 1300
G13: Other Deposts/Additions
G14: ACH Payments | J14: 5
G15: ACH Deposits
G16: Manual Checks
G17: Card Withdrawals
G18: Other Withdrawals | J18: 7
G21: Payee | H21: Description | K21: Inventory | M21: Promissory | O21: Labor | Q21: Fees
E22: Check#1017 | F22: 42401 | G22: King County | H22: Plan Review | J22: 645 | Q22: =J22 -> 645
E23: Check#1018 | F23: 42405 | G23: Kris Robbins | H23: Promissory Note#5 | J23: 579.98 | M23: =J23 -> 579.98

Sheet Mar
G4: Total Credits | J4: =SUM(J12:J24) -> 2800
G5: Total Debits | L5: =S30 -> 1600
G7: Net Income | J7: =J4-L5 -> 1200
G12: Deposits/Additions | J12: =I13+I14 -> 2800
H13: 42431 | I13: 1000
H14: 42452 | I14: 1800
G15: Other Deposts/Additions
G16: ACH Payments | L16: =K17+K18 -> 5.49
H17: 42431 | K17: 5
H18: 42443 | K18: 0.49
G19: ACH Deposits
H20: 42443 | I20: 0.49
H21: 42453 | I21: 30
G22: Manual Checks
G23: Card Withdrawals
G24: Other Withdrawals
H25: 42460 | K25: 7
G27: Payee | H27: Description | M27: Inventory | N27: Promissory | P27: Labor | R27: Fees | S27: Construction
E28: Check#1019 | F28: 42436 | G28: Kris Robbins | H28: Promissory#6 | K28: 579.98 | N28: 579.98
E29: Check#1020 | F29: 42453 | G29: Kris Robbins | H29: Promissory#7 | K29: 579.98 | N29: 579.98
E30: Check#1021 | F30: 42454 | G30: Jose Gomez | H30: Paint Job | K30: 1600 | S30: =K30 -> 1600

Sheet April
G4: Total Credits | J4: =J12 -> 6100
G5: Total Debits | K5: =SUM(K18:K32) -> 5211.56
G7: Net Income | J7: =J4-K5 -> 888.44
G12: Deposits/Additions | J12: =SUM(I13:I15) -> 6100
F13: 42461 | I13: 2400
F14: 42466 | I14: 2000
F15: 42479 | I15: 1700
G16: Other Deposts/Additions
G17: ACH Payments
F18: 42479 | K18: 10
G20: ACH Deposits
F21: 42443
F22: 42453
G23: Manual Checks
G24: Card Withdrawals
G25: Other Withdrawals
F26: 42490 | K26: 7
G28: Payee | H28: Description | M28: Inventory | N28: Promissory | P28: Labor | R28: Fees | S28: Construction
E29: Check#1022 | F29: 42464 | G29: Jose Gomez | H29: Paint job | K29: 1592 | S29: =K29 -> 1592
E30: Check#1023 | F30: 42466 | G30: Bole Design | H30: Furniture | K30: 2600 | S30: =K30 -> 2600
E31: Check#1024 | F31: 42479 | G31: Coca-Cola Refreshments | H31: Beverage Installation | K31: 422.58 | S31: =K31 -> 422.58
E32: Check#1025 | F32: 42485 | G32: Kris Robbins | H32: Promissory Note#8 | K32: 579.98 | N32: =K32 -> 579.98

Sheet May
G4: Total Credits | J4: =J13 -> 233.33
G5: Total Debits | L5: =L17+L25+L32 -> 1983.63
G7: Net Income | J7: =J4-L5 -> -1750.3
G12: Deposits/Additions
F13: 42499 | H13: Deposit | J13: 233.33
G16: Other Deposts/Additions
G17: ACH Payments | L17: =K18+K19 -> 238
F18: 42506 | G18: Square | K18: 13
F19: 42506 | G19: Kingswood | H19: Equipment Lease | K19: 225
G20: ACH Deposits
G23: Manual Checks
G24: Card Withdrawals
G25: Other Withdrawals | L25: =SUM(K26:K30) -> 84.2
F26: 42510 | K26: 2.2
F27: 42510 | K27: 35
F28: 42515 | K28: 35
F29: 42517 | K29: 5
F30: 43982 | H30: Service Charge | K30: 7
L32: =SUM(K34:K36) -> 1661.43
G33: Payee | H33: Description | M33: Inventory | N33: Promissory | P33: Labor | R33: Fees | S33: Construction
E34: Check#1026 | G34: Maneesh Chugh | H34: Speakers | K34: =S34 -> 306.45 | S34: 306.45
E35: Check#1027 | G35: Kris Robbins | H35: Promissory Note#9 | K35: =N35 -> 579.98 | N35: 579.98 | S35: =K35 -> 579.98
E36: Check#1028 | G36: Master Colors | H36: Flooring | K36: =S36 -> 775 | S36: 775

Sheet June
G4: Total Credits | J4: =SUM(J12:J26) -> 2203.19
G5: Total Debits | L5: =SUM(L12:L33) -> 1729.89
G7: Net Income | J7: =J4-L5 -> 473.3
G12: Deposits/Additions | J12: =SUM(I13:I15) -> 1776
F13: 42536 | H13: Deposit | I13: 1000
F14: 42538 | H14: Deposit | I14: 500
F15: 42550 | H15: Deposit | I15: 276
G17: Other Deposts/Additions
G18: ACH Payments | L18: =K19+K20 -> 949.91
F19: 42523 | G19: Square | H19: Square | K19: 19
F20: 43997 | G20: Pawnee | H20: Equipment Leasing | K20: 930.91
G21: ACH Deposits | J21: =I22+I23 -> 140.19
F22: 42551 | G22: Credit Square | I22: 139.7
F23: 42551 | G23: Credit Square | I23: 0.49
G24: Manual Checks
G25: Card Withdrawals
G26: Other Withdrawals | J26: =I27 -> 287
I27: 287
H31: Service Charge
L33: =SUM(K35:K38) -> 779.98
G34: Payee | H34: Description | M34: Inventory | N34: Promissory | P34: Labor | R34: Fees | S34: Construction
E35: Check#1029 | G35: Kris Robbins | H35: Promissory Note#10 | K35: 579.98 | N35: 579.98
E36: Check#1030 | G36: King County | H36: Filing Fee | K36: 25 | R36: 25
E37: Check#1031 | G37: Inventory | K37: 75 | M37: =K37 -> 75
E38: Check#1036 | G38: Inventory | K38: 100 | M38: =K38 -> 100

Sheet July
G4: Total Credits | J4: =J21 -> 3483.94
G5: Total Debits | L5: =SUM(L18:L39) -> 2989.47
G7: Net Income | J7: =J4-L5 -> 494.47
G12: Deposits/Additions
H13: Deposit
H14: Deposit
H15: Deposit
G17: Other Deposts/Additions
G18: ACH Payments | L18: =19 -> 19
F19: 42556 | G19: Square | H19: Square | K19: 19
G21: ACH Deposits | J21: =SUM(I22:I28) -> 3483.94
F22: 42552 | I22: 383.64
F23: 42552 | I23: 72.35
F24: 42556 | I24: 1433.98
F25: 42556 | I25: 845.81
F26: 42556 | I26: 73.35
F27: 42556 | I27: 31.12
F28: 42557 | I28: 643.69
G30: Manual Checks
G31: Card Withdrawals
G32: Other Withdrawals | L32: =SUM(K33:K35) -> 2470.47
F33: 42551 | G33: OD fee | K33: 5
F34: 42552 | G34: OD fee | K34: 5
F35: 42558 | G35: OTC Withdrawal | K35: 2460.47
H37: Service Charge
G39: Total Checks | L39: =K41 -> 500
G40: Payee | H40: Description | M40: Inventory | N40: Promissory | P40: Labor | R40: Fees | S40: Construction
E41: Check#1037 | G41: Griffin Richardson | H41: cleanup | K41: 500 | S41: =K41 -> 500
G43: overdraft fee | K43: 105 | R43: =K43 -> 105

Sheet Aug
G4: Total Credits
G5: Total Debits
G7: Net Income
G12: Deposits/Additions
H13: Deposit
H14: Deposit
H15: Deposit
G17: Other Deposts/Additions
G18: ACH Payments
G19: Square | H19: Square
G21: ACH Deposits
G30: Manual Checks
G31: Card Withdrawals
G32: Other Withdrawals
G33: OD fee
G34: OD fee
G35: OTC Withdrawal
H37: Service Charge
G39: Total Checks
G40: Payee | H40: Description | L40: Equip | M40: Inventory | N40: Promissory | P40: Labor | R40: Fees | S40: Construction
E41: Check# | P41: =K41 -> 0
G46: Card Transactions
G47: Payee | H47: Description | L47: Equip | M47: Inventory | N47: Promissory | O47: Broadband | P47: Misc Svcs | R47: Fees | S47: Construction
F48: 42590 | G48: Cash&Carry | H48: Groceries | I48: 75.99 | M48: 75.99
F49: 42592 | G49: Cash&Carry | H49: Groceries | I49: 48.76 | M49: =I49 -> 48.76
G50: Cash&Carry | H50: Groceries | I50: 132.18 | M50: =I50 -> 132.18
G51: comcast cable | I51: 365.73 | O51: =I51 -> 365.73
G52: Cash&Carry | H52: Groceries | I52: 269.96 | M52: =I52 -> 269.96
G53: Dick's Restaurant Supply | H53: Equipments | I53: 72.98 | L53: =I53 -> 72.98
G54: Cash&Carry | H54: Groceries | I54: 149.39 | M54: =I54 -> 149.39
G55: Cash&Carry | H55: Groceries | I55: 53.45 | M55: =I55 -> 53.45
G56: Craigslist | H56: Ad | I56: 45 | P56: =I56 -> 45
F57: 42611 | G57: Cash&Carry | H57: Groceries | I57: 25.48 | M57: =I57 -> 25.48
G59: health insurance | H59: molina | I59: 356.19 | P59: =I59 -> 356.19
I62: =SUM(I48:I59) -> 1595.11 | J62: =SUM(J48:J59) -> 0 | K62: =SUM(K48:K59) -> 0 | L62: =SUM(L48:L59) -> 72.98 | M62: =SUM(M48:M59) -> 755.21 | N62: =SUM(N48:N59) -> 0 | O62: =SUM(O48:O59) -> 365.73 | P62: =SUM(P48:P59) -> 401.19 | ... S62: =SUM(S48:S59) -> 0

Sheet Sep
G4: Total Credits | I4: =SUM(I13:I18) -> 2300
G5: Total Debits | J5: =SUM(J13:J18) -> 910.1
G7: Net Income | I7: =I4-J5 -> 1389.9
G13: Manual Deposts
G14: ACH Payments | J14: 208.62
G15: ACH Deposits | I15: 2300
G16: Manual Checks | J16: =J28 -> 0
G17: Card Withdrawals | J17: 644.48
G18: Other Withdrawal | J18: 57
G21: Payee
G22: Payee | H22: Description | L22: RENT | M22: Electricity | N22: Equip | O22: Inventory | P22: Promissory | Q22: Broadband | R22: labor | S22: Misc Svcs | U22: Fees | V22: Construction
J28: =SUM(J23:J26) -> 0
E31: Check#3026 | F31: 42620 | G31: Franz | H31: Bread | J31: 239.94 | O31: =J31 -> 239.94
E32: Check#3031 | F32: 42630 | G32: D&E Mercer Investments | H32: Rent | J32: 2000 | L32: =J32 -> 2000
E33: Check#3032 | F33: 42635 | G33: Advocate Telecom | H33: Low Voltage Wiring | J33: 213 | S33: =J33 -> 213
E34: Check#3034 | F34: 42637 | G34: PSE | H34: Electric Bill | J34: 1084.17 | M34: =J34 -> 1084.17
E35: Check#3035 | F35: 42638 | G35: Franz | H35: Bread | J35: 102.16 | O35: =J35 -> 102.16
E36: Check#3036 | F36: 42639 | G36: yesseny | J36: 74.48 | S36: =J36 -> 74.48
G39: Card Transactions
G40: Payee | H40: Description | L40: RENT | M40: Electricity | N40: Equip | O40: Inventory | P40: Promissory | Q40: Broadband | R40: labor | S40: Misc Svcs | U40: Fees | V40: Construction
D42: ACH | F42: 42614 | G42: ADP | H42: Payroll Tax | J42: =695.07 -> 695.07 | S42: =J42 -> 695.07
F43: 42614 | G43: ADP | H43: Payroll | J43: =2332.15 -> 2332.15 | R43: =J43 -> 2332.15
F44: 42622 | G44: ADP | H44: Payroll Fees | J44: 53.54 | U44: =J44 -> 53.54
F45: 42629 | G45: ADP | H45: Payroll Tax/401k | J45: 206.51 | S45: =J45 -> 206.51
F46: 42629 | G46: ADP | H46: Payroll | J46: 563.76 | R46: =J46 -> 563.76
F47: 42636 | G47: ADP | H47: Payroll Fees | J47: 42.84 | U47: =J47 -> 42.84
J49: =SUM(J31:J47) -> 7607.62 | L49: =SUM(L31:L47) -> 2000 | M49: =SUM(M31:M47) -> 1084.17 | N49: =SUM(N31:N47) -> 0 | O49: =SUM(O31:O47) -> 342.1 | P49: =SUM(P31:P47) -> 0 | Q49: =SUM(Q31:Q47) -> 0 | R49: =SUM(R31:R47) -> 2895.91 | S49: =SUM(S31:S47) -> 1189.06 | ... V49: =SUM(V31:V47) -> 0

Sheet Oct
G4: Total Credits | I4: =SUM(I13:I18) -> 0
G5: Total Debits | J5: =SUM(J13:J18) -> 793.1
G7: Net Income | I7: =I4-J5 -> -793.1
G12: Transfers | I12: 475.25
G13: Manual Deposts
G14: ACH Payments | J14: 97
G15: ACH Deposits
G16: Manual Checks | J16: =J28 -> 569.1
G17: Card Withdrawals
G18: Other Withdrawal | J18: 127
G22: Payee | H22: Description | L22: RENT | M22: Electricity | N22: Equipment | O22: Inventory | P22: Promissory | Q22: Broadband | S22: Labor | T22: Misc Svcs | U22: Fees | V22: Construction
E23: Check#3037 | F23: 42655 | G23: D&E Mercer Investments | H23: Rent October | J23: 2000 | L23: =J23 -> 2000 | O23: =J23 -> 2000
E24: Check#3038 | F24: 42659 | G24: Naresh Lakhanpal | J24: 488.49 | O24: =J24 -> 488.49
F27: 42646 | G27: ADP | H27: Tax/401K | J27: 151.1 | T27: =J27 -> 151.1
F28: 42646 | G28: ADP | H28: Payroll | J28: 569.1 | S28: =J28 -> 569.1
D29: ACH | F29: 42650 | G29: ADP | H29: Payroll Fees | J29: 42.84 | U29: =J29 -> 42.84
F30: 42654 | G30: Pawnee Leasing | H30: Equipment Lease | J30: 930.91 | N30: =J30 -> 930.91
F31: 42661 | G31: ADP | H31: Tax/401K | J31: 292.42 | T31: =J31 -> 292.42
F32: 42661 | G32: ADP | H32: Payroll | J32: 960 | S32: =J32 -> 960
F33: 42671 | G33: ADP | H33: Payroll Fees | J33: 67.84 | U33: =J33 -> 67.84
D36: Card Trns | F36: 42646 | G36: Facebook | H36: Ad | J36: 5 | U36: 5
F37: 42646 | G37: Quality Food | H37: Foods | J37: 14.21 | O37: 14.21
F38: 42647 | G38: Cash&Carry | J38: 66.07 | O38: =J38 -> 66.07
F39: 42654 | G39: Comcast | H39: Broadband | J39: 173.42 | Q39: =J39 -> 173.42
F40: 42660 | G40: Walmart | H40: foods | J40: 143.21 | O40: =J40 -> 143.21
F41: 42664 | G41: BestBuy | H41: equipment | J41: 101.66 | N41: 101.66
F42: 42664 | G42: Fred Meyer | H42: foods | J42: =30.65+16.41 -> 47.06 | O42: =J42 -> 47.06
F43: 42667 | G43: TimePayment | H43: Furniture Leasing | J43: 939.6 | N43: =J43 -> 939.6
F44: 42667 | G44: India Supermarket | H44: Food supplies | J44: 92.34 | O44: =J44 -> 92.34
J45: 108.45 | O45: =J45 -> 108.45
G46: marshalls | H46: decors | J46: 84.24 | N46: =J46 -> 84.24
G47: staples | J47: 100.73 | N47: =J47 -> 100.73
G48: walgreens | H48: food supplies | J48: 8.99 | O48: =J48 -> 8.99
G49: UPS | J49: 13.16 | U49: =J49 -> 13.16
G50: cash&carry | J50: 121.56 | O50: =J50 -> 121.56
G51: Albertsons | J51: 96.36 | O51: =J51 -> 96.36
J53: =SUM(J23:J51) -> 7618.76 | K53: =SUM(K23:K51) -> 0 | L53: =SUM(L23:L51) -> 2000 | M53: =SUM(M23:M51) -> 0 | N53: =SUM(N23:N51) -> 2157.14 | O53: =SUM(O23:O51) -> 3186.74 | P53: =SUM(P23:P51) -> 0 | Q53: =SUM(Q23:Q51) -> 173.42 | ... V53: =SUM(V23:V51) -> 0

Sheet Nov
G4: Total Credits | I4: =SUM(I13:I19) -> 2406.34
G5: Total Debits | J5: =SUM(J13:J19) -> 2205.22
G7: Net Income | I7: =I4-J5 -> 201.12
G12: Transfers | I12: 100
G13: Manual Deposts | I13: 2236.41
G14: Other Deposits | I14: 100
G15: ACH Payments | J15: 1830.47
G16: ACH Deposits | I16: 69.93
G17: Manual Checks | J17: =J29 -> 71.18
G18: Card Withdrawals | J18: 6.57
G19: Other Withdrawal | J19: 297
G23: Payee | H23: Description | L23: RENT | M23: Electricity | N23: Broadband | O23: equipment | P23: Inventory | Q23: Promissory | R23: Labor | S23: Misc Svcs | T23: Fees | U23: Construction
E24: Check#3040 | F24: 42684 | G24: Naresh Lakhanpal | H24: Grocery | J24: 97.88 | P24: =J24 -> 97.88
E25: Check#3041 | F25: 42689 | G25: Franz Bakery | H25: Bread | J25: 88.52 | P25: =J25 -> 88.52
E26: Check#3042 | F26: 42689 | G26: New System | H26: Laundry | J26: 71.1 | S26: =J26 -> 71.1
E27: Check#3043 | F27: 42689 | H27: Grocery | J27: 230 | P27: =J27 -> 230
E28: Check#3044 | F28: 42689 | G28: rehan dost | H28: Cleaning | J28: 366.67 | S28: =J28 -> 366.67
E29: Check#3045 | F29: 42695 | G29: New System | H29: Laundry | J29: 71.18 | S29: =J29 -> 71.18
E30: Check#3046 | J30: 69 | P30: =J30 -> 69
E31: Check#3047 | F31: 42697 | G31: ravi video | H31: supplies | J31: 430 | S31: =J31 -> 430
D33: ACH | F33: 42688 | G33: pawnee | H33: equipment leasing | J33: 930.91 | O33: =J33 -> 930.91
F34: 42690 | G34: ADP | H34: Tax/401K | J34: =55.72+103.34 -> 159.06 | S34: =J34 -> 159.06
F35: 42690 | G35: ADP | H35: PAYROLL | J35: 673.56 | R35: =J35 -> 673.56
F36: 42699 | G36: ADP | H36: payroll fees | J36: 91.14 | T36: =J36 -> 91.14
G37: homedepot | J37: 98 | U37: =J37 -> 98
D40: Card | F40: 42675 | G40: facebook | J40: 5 | T40: =J40 -> 5
F41: 42677 | G41: cash&carry | J41: 91.18 | P41: =J41 -> 91.18
F42: 42677 | G42: walmart | J42: 59.36 | P42: =J42 -> 59.36
F43: 42681 | G43: time payment | J43: 476.53 | O43: =J43 -> 476.53
F44: 42681 | G44: cash&carry | J44: 130.33 | P44: =J44 -> 130.33
F45: 42683 | G45: comcast | H45: cable | J45: 173.35 | N45: =J45 -> 173.35
F46: 42681 | G46: cash&carry | J46: 284.99 | P46: =J46 -> 284.99
F47: 42681 | G47: albertsons | J47: 155.54 | P47: =J47 -> 155.54
F48: 42681 | G48: dish | J48: 79.95 | S48: =J48 -> 79.95
J50: =SUM(J24:J48) -> 4833.25 | K50: =SUM(K24:K48) -> 0 | L50: =SUM(L24:L48) -> 0 | M50: =SUM(M24:M48) -> 0 | N50: =SUM(N24:N48) -> 173.35 | O50: =SUM(O24:O48) -> 1407.44 | P50: =SUM(P24:P48) -> 1206.8 | Q50: =SUM(Q24:Q48) -> 0 | ... U50: =SUM(U24:U48) -> 98

Sheet Dec
G4: Total Credits | I4: =SUM(I12:I19) -> 1326.74
G5: Total Debits | J5: =SUM(J12:J20) -> 434.46
G7: Net Income | I7: =I4-J5 -> 892.28
G12: Transfers | I12: 97
G13: Manual Deposts | I13: 1229.74
G14: Other Deposits
G15: ACH Payments | J15: 5
G16: ACH Deposits
G17: Manual Checks | J17: =J25 -> 332.46
G18: Card Withdrawals
G19: Other Withdrawals | J19: 97
G23: Payee | H23: Description | L23: RENT | M23: Electricity | N23: Mobile | O23: Inventory | P23: Promissory | Q23: LABOR | R23: Misc Svcs | S23: Fees | T23: Construction
E25: Check#3048 | F25: 42706 | G25: naresh lakhanpal | H25: groceries | J25: 332.46 | O25: =J25 -> 332.46
E26: Check#3049 | F26: 42707 | G26: New System | H26: Laundry | J26: 71.18 | R26: =J26 -> 71.18
D32: ACH | F32: 42705 | G32: Verizon | H32: Mobile | J32: 92.97 | N32: =J32 -> 92.97
F33: 42706 | G33: square | H33: processing fee | J33: =19+38.33 -> 57.33 | S33: =J33 -> 57.33
F34: 42706 | G34: ADP | H34: TAX/401K | J34: 225.16 | R34: =J34 -> 225.16
F35: 42706 | G35: ADP | H35: PAYROLL | J35: 825.87 | Q35: =J35 -> 825.87
F36: 42713 | G36: ADP | H36: processing fee | J36: 42.84 | S36: =J36 -> 42.84
F37: 42708
F38: 42719 | G38: Verizon | H38: Mobile | J38: 131.51 | N38: =J38 -> 131.51
F39: 42723 | G39: adp | H39: TAX/401K | J39: 379.48 | R39: =J39 -> 379.48
F40: 42723 | G40: adp | H40: PAYROLL | J40: 1051 | Q40: =J40 -> 1051
F41: 42727 | G41: adp | H41: processing fee | J41: 55.57 | S41: =J41 -> 55.57
F42: 42731 | G42: WA DOR | H42: Rev Taxes | J42: 129.75 | S42: =J42 -> 129.75
J44: =SUM(J25:J42) -> 3395.12 | K44: =SUM(K25:K42) -> 0 | L44: =SUM(L25:L42) -> 0 | M44: =SUM(M25:M42) -> 0 | N44: =SUM(N25:N42) -> 224.48 | O44: =SUM(O25:O42) -> 332.46 | P44: =SUM(P25:P42) -> 0 | Q44: =SUM(Q25:Q42) -> 1876.87 | ... T44: =SUM(T25:T42) -> 0

Sheet Categories
B2: Business Purchase
B4: Rent
B6: registration fee
B8: permit
B10: utilities
B12: garbage
B14: wifi
B16: food supplies
B18: furniture
B20: lights
B22: sound system
B24: concrete floor
... B36: ceiling
