Workbook

Sheet Summary
E1: INR to USD
E2: INR to CAD
E3: Mileage
E4: Home Use %
F5: =G5+1 -> 2024 | G5: =H5+1 -> 2023 | H5: =I5+1 -> 2022 | I5: =J5+1 -> 2021 | J5: =K5+1 -> 2020 | K5: =L5+1 -> 2019 | L5: =M5+1 -> 2018 | M5: 2017
E6: W2 Wages | H6: 37995.76 | I6: 49793.32 | J6: 69549.66 | K6: 84444.89 | L6: 70399.57 | M6: 63132.46
E7: Taxes Withheld | H7: 4063.44 | I7: 5834.02 | J7: 10423.75 | K7: 12386.28 | L7: 7675.56 | M7: 7909.36
E10: Biz Income/Loss
C11: work in progress | E11: 1. Comfort Foods (dba Robertos Pizza) | M11: =Robertos!D3-Robertos!D4 -> -44581.92
E12: 2. CloudBaud LLC | F12: ='CB-24'!C6 -> 153952 | G12: ='CB-23'!C6 -> 38376 | H12: ='CB-22'!C6 -> 365772.34 | I12: ='CB-21'!C6 -> 67285.005 | J12: ='CB-20'!C6 -> -1569.8499 | K12: ='CB-19'!D6 -> 79825.513 | L12: ='CB-18'!C3 -> 485019.41 | M12: ='CB-17'!C6 -> 334565.42
C13: question for IRS or CPA | E13: 3. Teaching Income
E14: 4. Canada Condo Sale
C15: complete for CPA | E15: Rental Income
E16: 1. Olympic Court
C17: filed with CPA | E17: 2. Cherry Crest
E18: 3. Woodridge
C19: filed with IRS
E21: Jishnu Roth IRA | M21: 5500
E22: Deepika ROTH IRA | L22: 5500 | M22: 5500
E23: SEP IRA | L23: 43605.6 | M23: 5244.9
E24: 1099-R | L24: 4862.99 | M24: 0
E25: Child Education Fund | M25: 4000
E27: Itemized deductions
E28: Real Estate Interest Woodridge | I28: 10516.14 | J28: 16431.02 | K28: 18719.36 | L28: 13698.52 | M28: 17619.67
E29: Real Estate Interest Lake Hills
E30: Real Estate Interest Olympic Court
E32: Real Estate Taxes Woodridge | I32: 7271.09 | J32: 7191.32 | K32: 6633.65 | L32: 6191.31 | M32: 5009.22
E33: Real Estate Taxes Cherry Crest | I33: 4110.17 | J33: 3186.17 | K33: 2724.69 | L33: 2761.75
E34: Real Estate Taxes Lake Hills
E35: Real Estate Taxes Olympic Court
E36: Real Estate Taxes Rudins Lounge
E41: Capital Gains/Loss | M41: =-1*32307.82 -> -32307.82
E42: Investment Interest | M42: 115.94
E44: Gifts to Charity | G44: Rs. 50000 | H44: =51 -> 51 | M44: 500
E47: Medical/Dental HSA | L47: 5800 | M47: 4050
I75: 7

Sheet LH-23
C2: keys, packing
C3: grass cutting | D3: 250

Sheet WR-23

Sheet CB-24
B1: =Summary!F5 -> 2024 | G1: ="CLOUDBAUD CONSULTING "& Summary!F5 & " ONLY" -> CLOUDBAUD CONSULTING 2024 ONLY
F2: TOTAL | G2: Jan | H2: Feb | I2: Mar | J2: Apr | K2: May | L2: Jun | M2: Jul | N2: Aug | O2: Sep | P2: Oct | Q2: Nov | R2: Dec | T2: Check# | U2: Amount | V2: Date | W2: Payee
B3: ='CB-17'!B3 -> CONSULTING REVENUE | C3: =F3 -> 153952 | F3: =SUM(G3:R3) -> 153952 | G3: =8496 -> 8496 | H3: 0 | I3: =7168 -> 7168 | J3: =18816 -> 18816 | K3: 0 | L3: =6272+15840 -> 22112 | M3: =19712 -> 19712 | N3: =17600+1792 -> 19392 | O3: 38720 | P3: 19536 | Q3: 0 | R3: 0
F4: YTD | G4: =G3 -> 8496 | H4: =G4+H3 -> 8496 | I4: =H4+I3 -> 15664 | J4: =I4+J3 -> 34480 | K4: =J4+K3 -> 34480 | L4: =K4+L3 -> 56592 | M4: =L4+M3 -> 76304 | N4: =M4+N3 -> 95696 | O4: =N4+O3 -> 134416 | ... R4: =Q4+R3 -> 153952
B5: ='CB-17'!B5 -> TOTAL EXPENSES | C5: =C7+C20+C27+C76+C35+C59+C45+C62+C67+C71 -> 0
B6: ='CB-17'!B6 -> NET REVENUE | C6: =C3-C5 -> 153952
B7: UTILITIES | C7: =SUM(D8:D14) -> 0 | D7: Prorated | E7: Rate | F7: Annual | G7: =SUM(G8:G14) -> 0 | H7: =SUM(H8:H14) -> 0 | I7: =SUM(I8:I14) -> 0 | J7: =SUM(J8:J14) -> 0 | K7: =SUM(K8:K14) -> 0 | L7: =SUM(L8:L14) -> 0 | M7: =SUM(M8:M14) -> 0 | N7: =SUM(N8:N14) -> 0 | ... R7: =SUM(R8:R14) -> 0
B8: ELECTRICITY | D8: =E8*F8 -> 0 | E8: 0.17 | F8: =SUM(G8:R8) -> 0
B9: WASTE | D9: =E9*F9 -> 0 | E9: 0.17 | F9: =SUM(G9:R9) -> 0
B10: Water | D10: =E10*F10 -> 0 | E10: 0.17 | F10: =SUM(G10:R10) -> 0
B11: Security | D11: =E11*F11 -> 0 | E11: 0.17 | F11: =SUM(G11:R11) -> 0
B12: Landscaping | D12: =E12*F12 -> 0 | E12: 0.17 | F12: =SUM(G12:R12) -> 0
B13: Home Owners Insurance | D13: =E13*F13 -> 0 | E13: 0.17 | F13: =SUM(G13:R13) -> 0
B14: Appliance Maintenance | D14: =E14*F14 -> 0 | E14: 0.17 | F14: =SUM(G14:R14) -> 0
B16: Mobile | C16: =D16 -> 0 | D16: =F16*E16 -> 0 | E16: 0.5 | F16: =SUM(G16:R16) -> 0
B17: Mobile Device (samsung) | E17: 1
B19: Biz Registration | C19: =F19 -> 0 | E19: 1 | F19: =SUM(G19:R19) -> 0
B20: WA DOR | C20: =F20 -> 0 | E20: 1 | F20: =SUM(G20:R20) -> 0
B21: Garnishment Fee | C21: =F21 -> 0 | E21: 1 | F21: =SUM(G21:R21) -> 0
B22: LNI Insurance | C22: =F22 -> 0 | E22: 1 | F22: =SUM(G22:R22) -> 0
B23: WA Employment Security
B24: Commercial Insurance | C24: =F24 -> 0 | E24: 1
B25: Supplies | C25: =F25 -> 40.34 | E25: 1 | F25: =SUM(G25:R25) -> 40.34 | H25: 40.34
B26: STATIONARIES | C26: =F26 -> 0 | E26: 1 | F26: =SUM(G26:R26) -> 0
B27: PAYROLL | C27: =SUM(F28:F31) -> 0 | E27: Rate
D28: =F28*E28 -> 0 | E28: 1 | F28: =SUM(G28:R28) -> 0
D29: =F29*E29 -> 0 | E29: 1 | F29: =SUM(G29:R29) -> 0
D30: =F30*E30 -> 0 | E30: 1 | F30: =SUM(G30:R30) -> 0
D31: =F31*E31 -> 0 | E31: 1 | F31: =SUM(H31:R31) -> 0
A33: godaddy | B33: WEB HOSTING | F33: =SUM(G33:R33) -> 0
A34: xfiniti | B34: BROADBAND | E34: 0.5 | F34: =SUM(G34:R34) -> 0
A35: t-mobile | B35: Logo Services | F35: =SUM(G35:R35) -> 0
A36: logo | B36: Temp Services | F36: =SUM(G36:R36) -> 0
A37: misc. | B37: Professional Services | C37: =E37 -> 0 | E37: =SUM(G37:R37) -> 0
B38: Bank Fees | C38: =E38 -> 0 | E38: =SUM(G38:R38) -> 0
B39: RENOVATION | C39: =SUM(F40:F43) -> 800
B40: Flooring | F40: =SUM(G40:R40) -> 0 | T40: 3044 | U40: 330 | V40: 44766 | W40: Edilberto
B41: Paint | F41: =SUM(G41:R41) -> 0 | T41: 3583 | U41: 300 | V41: 44745 | W41: SEARS
B42: bathroom | F42: =SUM(G42:R42) -> 0 | T42: 9917 | U42: 200 | V42: 44760 | W42: BoA
B43: electrical work | F43: 800 | T43: 3022 | U43: 570 | V43: 44779 | W43: Edilberto
...

Sheet CB-23
B1: =Summary!G5 -> 2023 | G1: ="CLOUDBAUD CONSULTING "& Summary!G5 & " ONLY" -> CLOUDBAUD CONSULTING 2023 ONLY
F2: TOTAL | G2: Jan | H2: Feb | I2: Mar | J2: Apr | K2: May | L2: Jun | M2: Jul | N2: Aug | O2: Sep | P2: Oct | Q2: Nov | R2: Dec | T2: Check# | U2: Amount | V2: Date | W2: Payee
B3: ='CB-17'!B3 -> CONSULTING REVENUE | C3: =F3 -> 39176 | F3: =SUM(G3:R3) -> 39176 | P3: 0 | Q3: =10384+1888 -> 12272 | R3: =10620+ 16284 -> 26904
F4: YTD | G4: =G3 -> 0 | H4: =G4+H3 -> 0 | I4: =H4+I3 -> 0 | J4: =I4+J3 -> 0 | K4: =J4+K3 -> 0 | L4: =K4+L3 -> 0 | M4: =L4+M3 -> 0 | N4: =M4+N3 -> 0 | O4: =N4+O3 -> 0 | ... R4: =Q4+R3 -> 39176
B5: ='CB-17'!B5 -> TOTAL EXPENSES | C5: =C7+C20+C27+C76+C35+C59+C45+C62+C67+C71 -> 800
B6: ='CB-17'!B6 -> NET REVENUE | C6: =C3-C5 -> 38376
B7: UTILITIES | C7: =SUM(D8:D14) -> 0 | D7: Prorated | E7: Rate | F7: Annual | G7: =SUM(G8:G14) -> 0 | H7: =SUM(H8:H14) -> 0 | I7: =SUM(I8:I14) -> 0 | J7: =SUM(J8:J14) -> 0 | K7: =SUM(K8:K14) -> 0 | L7: =SUM(L8:L14) -> 0 | M7: =SUM(M8:M14) -> 0 | N7: =SUM(N8:N14) -> 0 | ... R7: =SUM(R8:R14) -> 0
B8: ='CB-17'!B8 -> Electricity | C8: ='CB-17'!C8 -> 380.358 | D8: =E8*F8 -> 0 | E8: ='CB-17'!E8 -> 0.17 | F8: =SUM(G8:R8) -> 0
B9: ='CB-17'!B9 -> Waste & Recycle | C9: ='CB-17'!C9 -> 68.6137 | D9: =E9*F9 -> 0 | E9: ='CB-17'!E9 -> 0.17 | F9: =SUM(G9:R9) -> 0
B10: ='CB-17'!B10 -> Water & Sewer | C10: ='CB-17'!C10 -> 0 | D10: =E10*F10 -> 0 | E10: ='CB-17'!E10 -> 0.17 | F10: =SUM(G10:R10) -> 0
B11: ='CB-17'!B11 -> Security | C11: ='CB-17'!C11 -> 0 | D11: =E11*F11 -> 0 | E11: ='CB-17'!E11 -> 0.17 | F11: =SUM(G11:R11) -> 0
B12: ='CB-17'!B12 -> Landscaping | C12: ='CB-17'!C12 -> 0 | D12: =E12*F12 -> 0 | E12: ='CB-17'!E12 -> 0.17 | F12: =SUM(G12:R12) -> 0
B13: ='CB-17'!B13 -> Home Owners Insurance | C13: ='CB-17'!C13 -> 0 | D13: =E13*F13 -> 0 | E13: ='CB-17'!E13 -> 0.17 | F13: =SUM(G13:R13) -> 0
B14: ='CB-17'!B14 -> Appliance Maintenance | C14: ='CB-17'!C14 -> 0 | D14: =E14*F14 -> 0 | E14: ='CB-17'!E14 -> 0.5 | F14: =SUM(G14:R14) -> 0
B15: ='CB-17'!B15 -> Apple Warranty | C15: ='CB-17'!C15 -> 0 | D15: =E15*F15 -> 0 | E15: ='CB-17'!E15 -> 0.5 | F15: =SUM(G15:R15) -> 0
B16: ='CB-17'!B16 -> Computers Warranty | C16: ='CB-17'!C16 -> 0 | D16: =E16*F16 -> 0 | E16: ='CB-17'!E16 -> 0.5 | F16: =SUM(G16:R16) -> 0
B17: ='CB-17'!B17 -> Cellular Service | C17: ='CB-17'!C17 -> 0 | D17: =E17*F17 -> 0 | E17: ='CB-17'!E17 -> 0.5 | F17: =SUM(G17:R17) -> 0
B18: ='CB-17'!B18 -> Broadband | C18: ='CB-17'!C18 -> 0 | D18: =E18*F18 -> 0 | E18: ='CB-17'!E18 -> 0.5 | F18: =SUM(G18:R18) -> 0
B19: ='CB-17'!B19 -> TV Cable | C19: ='CB-17'!C19 -> 0 | D19: =E19*F19 -> 0 | E19: ='CB-17'!E19 -> 0.5 | F19: =SUM(G19:R19) -> 0
B20: ='CB-17'!B20 -> DEPRECIABLE ASSETS | G20: =SUM(G21:G26) -> 0 | H20: =SUM(H21:H26) -> 0 | I20: =SUM(I21:I26) -> 0 | J20: =SUM(J21:J26) -> 0 | K20: =SUM(K21:K26) -> 0 | L20: =SUM(L21:L26) -> 0 | M20: =SUM(M21:M26) -> 0 | N20: =SUM(N21:N26) -> 0 | ... R20: =SUM(R21:R26) -> 0
B27: Biz Registration | C27: =F27 -> 0 | E27: 1 | F27: =SUM(G27:R27) -> 0
B28: WA DOR | C28: =F28 -> 0 | E28: 1 | F28: =SUM(G28:R28) -> 0
B29: Garnishment Fee | C29: =F29 -> 0 | E29: 1 | F29: =SUM(G29:R29) -> 0
B30: LNI Insurance | C30: =F30 -> 0 | E30: 1 | F30: =SUM(G30:R30) -> 0
B31: WA Employment Security
B32: Commercial Insurance | C32: =F32 -> 0 | E32: 1
A33: godaddy | B33: Supplies | C33: =F33 -> 40.34 | E33: 1 | F33: =SUM(G33:R33) -> 40.34 | H33: 40.34
A34: xfiniti | B34: STATIONARIES | C34: =F34 -> 0 | E34: 1 | F34: =SUM(G34:R34) -> 0
A35: t-mobile | D35: =F35*E35 -> 0 | E35: 1 | F35: =SUM(G35:R35) -> 0
A36: logo | D36: =F36*E36 -> 0 | E36: 1 | F36: =SUM(G36:R36) -> 0
A37: misc. | D37: =F37*E37 -> 0 | E37: 1 | F37: =SUM(H37:R37) -> 0
B39: WEB HOSTING | F39: =SUM(G39:R39) -> 0
B40: BROADBAND | E40: 0.5 | F40: =SUM(G40:R40) -> 0 | T40: 3044 | U40: 330 | V40: 44766 | W40: Edilberto
B41: Logo Services | F41: =SUM(G41:R41) -> 0 | T41: 3583 | U41: 300 | V41: 44745 | W41: SEARS
B42: Temp Services | F42: =SUM(G42:R42) -> 0 | T42: 9917 | U42: 200 | V42: 44760 | W42: BoA
B43: Professional Services | C43: =E43 -> 0 | E43: =SUM(G43:R43) -> 0 | T43: 3022 | U43: 570 | V43: 44779 | W43: Edilberto
B44: Bank Fees | C44: =E44 -> 0 | E44: =SUM(G44:R44) -> 0 | T44: 3023 | U44: 350 | V44: 44779 | W44: Edilberto
B45: RENOVATION | C45: =SUM(F46:F49) -> 800 | T45: 3024 | U45: 151 | V45: 44794 | W45: Edilberto
B46: Flooring | F46: =SUM(G46:R46) -> 0 | T46: 3025 | U46: 180 | V46: 44794 | W46: Edilberto
B47: Paint | F47: =SUM(G47:R47) -> 0 | T47: 3584 | U47: 300 | V47: 44776 | W47: SEARS
...

Sheet CB-22
B1: =Summary!H5 -> 2022 | G1: ="CLOUDBAUD CONSULTING "& Summary!H5 & " ONLY" -> CLOUDBAUD CONSULTING 2022 ONLY
F2: TOTAL | G2: Jan | H2: Feb | I2: Mar | J2: Apr | K2: May | L2: Jun | M2: Jul | N2: Aug | O2: Sep | P2: Oct | Q2: Nov | R2: Dec | T2: Check# | U2: Amount | V2: Date | W2: Payee
B3: ='CB-17'!B3 -> CONSULTING REVENUE | C3: =F3 -> 366830.49 | F3: =SUM(G3:R3) -> 366830.49 | G3: =24030 -> 24030 | H3: =15080+24030 -> 39110 | I3: =22815+8700 -> 31515 | J3: =14065+19035 -> 33100 | K3: 18560 | L3: =18270+41985 -> 60255 | M3: =6075+18270+22815 -> 47160 | N3: =25245+17835 -> 43080 | O3: 20010 | P3: =29010.49 -> 29010.49 | Q3: 0 | R3: =21000 -> 21000
F4: YTD | G4: =G3 -> 24030 | H4: =G4+H3 -> 63140 | I4: =H4+I3 -> 94655 | J4: =I4+J3 -> 127755 | K4: =J4+K3 -> 146315 | L4: =K4+L3 -> 206570 | M4: =L4+M3 -> 253730 | N4: =M4+N3 -> 296810 | O4: =N4+O3 -> 316820 | ... R4: =Q4+R3 -> 366830.49
B5: ='CB-17'!B5 -> TOTAL EXPENSES | C5: =C7+C20+C27+C76+C35+C59+C45+C62+C67+C71 -> 1058.1463
B6: ='CB-17'!B6 -> NET REVENUE | C6: =C3-C5 -> 365772.34
B7: UTILITIES | C7: =SUM(D8:D14) -> 1058.1463 | D7: Prorated | E7: Rate | F7: Annual | G7: =SUM(G8:G14) -> 1171.42 | H7: =SUM(H8:H14) -> 688.25 | I7: =SUM(I8:I14) -> 200.54 | J7: =SUM(J8:J14) -> 287.86 | K7: =SUM(K8:K14) -> 1300.54 | L7: =SUM(L8:L14) -> 473.27 | M7: =SUM(M8:M14) -> 528.96 | N7: =SUM(N8:N14) -> 328.28 | ... R7: =SUM(R8:R14) -> 200.54
B8: ='CB-17'!B8 -> Electricity | C8: =D8 -> 564.3405 | D8: =E8*F8 -> 564.3405 | E8: ='CB-17'!E8 -> 0.17 | F8: =SUM(G8:R8) -> 3319.65 | G8: 944.98 | H8: 366.63 | I8: 0 | J8: 0 | K8: 1100 | L8: 272.73 | M8: 151.78 | N8: 127.74 | O8: 177.71 | P8: 178.08 | Q8: 0 | R8: 0
B9: ='CB-17'!B9 -> Waste & Recycle | C9: =D9 -> 74.4124 | D9: =E9*F9 -> 74.4124 | E9: ='CB-17'!E9 -> 0.17 | F9: =SUM(G9:R9) -> 437.72 | G9: 86.44 | J9: 87.32 | M9: 176.64 | P9: 87.32
B10: ='CB-17'!B10 -> Water & Sewer | C10: =D10 -> 0 | D10: =E10*F10 -> 0 | E10: ='CB-17'!E10 -> 0.17 | F10: =SUM(G10:R10) -> 0
B11: ='CB-17'!B11 -> Security | C11: =D11 -> 133.7934 | D11: =E11*F11 -> 133.7934 | E11: ='CB-17'!E11 -> 0.17 | F11: =SUM(G11:R11) -> 787.02 | G11: 0 | H11: 181.62 | I11: 60.54 | J11: 60.54 | K11: 60.54 | L11: 60.54 | M11: 60.54 | N11: 60.54 | O11: 60.54 | P11: 60.54 | Q11: 60.54 | R11: 60.54
B12: ='CB-17'!B12 -> Landscaping | C12: =D12 -> 285.6 | D12: =E12*F12 -> 285.6 | E12: ='CB-17'!E12 -> 0.17 | F12: =SUM(G12:R12) -> 1680 | G12: 140 | H12: 140 | I12: 140 | J12: 140 | K12: 140 | L12: 140 | M12: 140 | N12: 140 | O12: 140 | P12: 140 | Q12: 140 | R12: 140
B13: ='CB-17'!B13 -> Home Owners Insurance | C13: =D13 -> 0 | D13: =E13*F13 -> 0 | E13: ='CB-17'!E13 -> 0.17 | F13: =SUM(G13:R13) -> 0
B14: ='CB-17'!B14 -> Appliance Maintenance | C14: =D14 -> 0 | D14: =E14*F14 -> 0 | E14: ='CB-17'!E14 -> 0.5 | F14: =SUM(G14:R14) -> 0
B15: ='CB-17'!B15 -> Apple Warranty | C15: =D15 -> 0 | D15: =E15*F15 -> 0 | E15: ='CB-17'!E15 -> 0.5 | F15: =SUM(G15:R15) -> 0
B16: ='CB-17'!B16 -> Computers Warranty | C16: =D16 -> 0 | D16: =E16*F16 -> 0 | E16: ='CB-17'!E16 -> 0.5 | F16: =SUM(G16:R16) -> 0
B17: ='CB-17'!B17 -> Cellular Service | C17: =D17 -> 0 | D17: =E17*F17 -> 0 | E17: ='CB-17'!E17 -> 0.5 | F17: =SUM(G17:R17) -> 0
B18: ='CB-17'!B18 -> Broadband | C18: =D18 -> 0 | D18: =E18*F18 -> 0 | E18: ='CB-17'!E18 -> 0.5 | F18: =SUM(G18:R18) -> 0
B19: ='CB-17'!B19 -> TV Cable | C19: =D19 -> 0 | D19: =E19*F19 -> 0 | E19: ='CB-17'!E19 -> 0.5 | F19: =SUM(G19:R19) -> 0
B20: ='CB-17'!B20 -> DEPRECIABLE ASSETS | C20: =SUM(C21:C26) -> 0 | D20: Prorated | E20: Rate | F20: Annual | G20: =SUM(G21:G26) -> 0 | H20: =SUM(H21:H26) -> 0 | I20: =SUM(I21:I26) -> 0 | J20: =SUM(J21:J26) -> 0 | K20: =SUM(K21:K26) -> 0 | L20: =SUM(L21:L26) -> 0 | M20: =SUM(M21:M26) -> 0 | N20: =SUM(N21:N26) -> 0 | ... R20: =SUM(R21:R26) -> 0
B21: ='CB-17'!B21 -> ASUS Laptop | C21: =D21 -> 0 | D21: =E21*F21 -> 0 | E21: ='CB-17'!E21 -> 0.5 | F21: =SUM(G21:R21) -> 0
B22: ='CB-17'!B22 -> Mobile Device (samsung) | C22: =D22 -> 0 | D22: =E22*F22 -> 0 | E22: ='CB-17'!E22 -> 0.5 | F22: =SUM(G22:R22) -> 0
B23: ='CB-17'!B23 -> Cellphone Device | C23: =D23 -> 0 | D23: =E23*F23 -> 0 | E23: ='CB-17'!E23 -> 0.5 | F23: =SUM(G23:R23) -> 0
B24: ='CB-17'!B24 -> Supplies | C24: =D24 -> 0 | D24: =E24*F24 -> 0 | E24: ='CB-17'!E24 -> 1 | F24: =SUM(G24:R24) -> 0
B25: ='CB-17'!B25 -> Stationaries | C25: =D25 -> 0 | D25: =E25*F25 -> 0 | E25: ='CB-17'!E25 -> 1 | F25: =SUM(G25:R25) -> 0
B26: ='CB-17'!B26 -> Books | C26: =D26 -> 0 | D26: =E26*F26 -> 0 | E26: ='CB-17'!E26 -> 1 | F26: =SUM(G26:R26) -> 0
B27: ='CB-17'!B27 -> GOVERNMENT FEES | C27: =SUM(C28:C34) -> 0 | D27: Prorated | E27: Rate | F27: Annual
B28: ='CB-17'!B28 -> Biz Registration | C28: =D28 -> 0 | D28: =E28*F28 -> 0 | E28: ='CB-17'!E28 -> 1 | F28: =SUM(G28:R28) -> 0
B29: ='CB-17'!B29 -> Licensing | C29: =D29 -> 0 | D29: =E29*F29 -> 0 | E29: ='CB-17'!E29 -> 1 | F29: =SUM(G29:R29) -> 0
B30: ='CB-17'!B30 -> WA DOR Excise Tax | C30: =D30 -> 0 | D30: =E30*F30 -> 0 | E30: ='CB-17'!E30 -> 1 | F30: =SUM(G30:R30) -> 0
B31: ='CB-17'!B31 -> Garnishment Fee | C31: =F31 -> 0 | D31: =E31*F31 -> 0 | E31: ='CB-17'!E31 -> 1 | F31: =SUM(G31:R31) -> 0
B32: ='CB-17'!B32 -> LNI Insurance | C32: =F32 -> 0 | D32: =E32*F32 -> 0 | E32: ='CB-17'!E32 -> 1 | F32: =SUM(G32:R32) -> 0
A33: godaddy | B33: ='CB-17'!B33 -> WA Employment Security | C33: =F33 -> 0 | D33: =E33*F33 -> 0 | E33: ='CB-17'!E33 -> 1 | F33: =SUM(G33:R33) -> 0
A34: xfiniti | B34: ='CB-17'!B34 -> Commercial Insurance | C34: =F34 -> 0 | D34: =E34*F34 -> 0 | E34: ='CB-17'!E34 -> 1 | F34: =SUM(G34:R34) -> 0
A35: misc. | B35: ='CB-17'!B35 -> PROFESSIONAL SERVICES | C35: =SUM(C36:C44) -> 0 | D35: Prorated | E35: Rate | F35: Annual
B36: ='CB-17'!B36 -> Web Domains | C36: =D36 -> 0 | D36: =F36*E36 -> 0 | E36: ='CB-17'!E36 -> 1 | F36: =SUM(G36:R36) -> 0
B37: ='CB-17'!B37 -> Web Hosting | C37: =D37 -> 0 | D37: =F37*E37 -> 0 | E37: ='CB-17'!E37 -> 1 | F37: =SUM(G37:R37) -> 0
B38: ='CB-17'!B38 -> Digital Ads | C38: =D38 -> 0 | D38: =F38*E38 -> 0 | E38: ='CB-17'!E38 -> 1 | F38: =SUM(G38:R38) -> 0 | T38: 3044 | U38: 330 | V38: 44766 | W38: Edilberto
B39: ='CB-17'!B39 -> Logo Services | C39: =D39 -> 0 | D39: =F39*E39 -> 0 | E39: ='CB-17'!E39 -> 1 | F39: =SUM(G39:R39) -> 0 | T39: 3583 | U39: 300 | V39: 44745 | W39: SEARS
B40: ='CB-17'!B40 -> Temp Services | C40: =D40 -> 0 | D40: =F40*E40 -> 0 | E40: ='CB-17'!E40 -> 1 | F40: =SUM(G40:R40) -> 0 | T40: 9917 | U40: 200 | V40: 44760 | W40: BoA
...

Sheet CB-21
A1: =Summary!I5 -> 2021 | B1: =Summary!I5 -> 2021 | G1: ="CLOUDBAUD CONSULTING "& Summary!I5 & " ONLY" -> CLOUDBAUD CONSULTING 2021 ONLY
A2: ='CB-20'!A2 -> Sources | F2: TOTAL | G2: Jan | H2: Feb | I2: Mar | J2: Apr | K2: May | L2: Jun | M2: July | N2: Aug | O2: Sep | P2: Oct | Q2: Nov | R2: Dec
A3: ='CB-20'!A3 -> Various | B3: ='CB-17'!B3 -> CONSULTING REVENUE | C3: =F3 -> 74480 | F3: =SUM(G3:R3) -> 74480 | G3: 0 | H3: 0 | I3: 17600 | J3: 18000 | K3: 19200 | L3: 0 | M3: 0 | N3: 0 | O3: 0 | P3: 0 | Q3: 1320 | R3: 18360
F4: YTD | G4: =G3 -> 0 | H4: =G4+H3 -> 0 | I4: =H4+I3 -> 17600 | J4: =I4+J3 -> 35600 | K4: =J4+K3 -> 54800 | L4: =K4+L3 -> 54800 | M4: =L4+M3 -> 54800 | N4: =M4+N3 -> 54800 | O4: =N4+O3 -> 54800 | ... R4: =Q4+R3 -> 74480
B5: ='CB-17'!B5 -> TOTAL EXPENSES | C5: =C7+C20+C27+C76+C35+C59+C45+C62+C67+C71 -> 7194.995
B6: ='CB-17'!B6 -> NET REVENUE | C6: =C3-C5 -> 67285.005
B7: ='CB-17'!B7 -> UTILITIES | C7: =SUM(C8:C21) -> 3142.1283 | D7: Prorated | E7: Rate | F7: Annual | G7: =SUM(G8:G19) -> 816.92 | H7: =SUM(H8:H19) -> 913.95 | I7: =SUM(I8:I19) -> 841.71 | J7: =SUM(J8:J19) -> 993.07 | K7: =SUM(K8:K19) -> 400.57 | L7: =SUM(L8:L19) -> 891.77 | M7: =SUM(M8:M19) -> 1208.51 | N7: =SUM(N8:N19) -> 1203.18 | ... R7: =SUM(R8:R19) -> 1145.55
B8: ='CB-17'!B8 -> Electricity | C8: =D8 -> 650.8076 | D8: =E8*F8 -> 650.8076 | E8: ='CB-17'!E8 -> 0.17 | F8: =SUM(G8:R8) -> 3828.28 | G8: 525.55 | H8: 310.79 | I8: 631.72 | J8: 254.37 | K8: 190.58 | L8: 169.63 | M8: 142.85 | N8: 308.34 | O8: 146.34 | P8: 142.14 | Q8: 375.45 | R8: 630.52
B9: ='CB-17'!B9 -> Waste & Recycle | C9: =D9 -> 55.4812 | D9: =E9*F9 -> 55.4812 | E9: ='CB-17'!E9 -> 0.17 | F9: =SUM(G9:R9) -> 326.36 | G9: 81.38 | J9: 81.66 | M9: 81.66 | R9: 81.66
B10: ='CB-17'!B10 -> Water & Sewer | C10: =D10 -> 434.1154 | D10: =E10*F10 -> 434.1154 | E10: ='CB-17'!E10 -> 0.17 | F10: =SUM(G10:R10) -> 2553.62 | H10: 393.17 | J10: 447.05 | L10: 421.14 | N10: 436.48 | P10: 855.78
B11: ='CB-17'!B11 -> Security | C11: =D11 -> 130.4291 | D11: =E11*F11 -> 130.4291 | E11: ='CB-17'!E11 -> 0.17 | F11: =SUM(G11:R11) -> 767.23 | M11: =464.52+60.55 -> 525.07 | Q11: 242.16
B12: ='CB-17'!B12 -> Landscaping | C12: =D12 -> 285.6 | D12: =E12*F12 -> 285.6 | E12: ='CB-17'!E12 -> 0.17 | F12: =SUM(G12:R12) -> 1680 | G12: 140 | H12: 140 | I12: 140 | J12: 140 | K12: 140 | L12: 140 | M12: 140 | N12: 140 | O12: 140 | P12: 140 | Q12: 140 | R12: 140
B13: ='CB-17'!B13 -> Home Owners Insurance | C13: =D13 -> 283.39 | D13: =E13*F13 -> 283.39 | E13: ='CB-17'!E13 -> 0.17 | F13: ='Home Insurance'!H13 -> 1667
B14: ='CB-17'!B14 -> Appliance Maintenance | C14: =D14 -> 279.96 | D14: =E14*F14 -> 279.96 | E14: ='CB-17'!E14 -> 0.5 | F14: =SUM(G14:R14) -> 559.92 | G14: 69.99 | H14: 69.99 | I14: 69.99 | J14: 69.99 | K14: 69.99 | L14: 0 | M14: 69.99 | N14: 69.99 | O14: 69.99 | P14: 0 | Q14: 0 | R14: 0
B15: ='CB-17'!B15 -> Apple Warranty | C15: =D15 -> 0 | D15: =E15*F15 -> 0 | E15: ='CB-17'!E15 -> 0.5 | F15: =SUM(G15:R15) -> 0
B16: ='CB-17'!B16 -> Computers Warranty | C16: =D16 -> 0 | D16: =E16*F16 -> 0 | E16: ='CB-17'!E16 -> 0.5 | F16: =SUM(G16:R16) -> 0
B17: ='CB-17'!B17 -> Cellular Service | C17: =D17 -> 393 | D17: =E17*F17 -> 393 | E17: ='CB-17'!E17 -> 0.5 | F17: =SUM(G17:R17) -> 786 | L17: 161 | M17: 145 | N17: 145 | P17: 145 | R17: 190
B18: ='CB-17'!B18 -> Broadband | C18: =D18 -> 340.395 | D18: =E18*F18 -> 340.395 | E18: ='CB-17'!E18 -> 0.5 | F18: =SUM(G18:R18) -> 680.79 | M18: 103.94 | N18: 103.37 | O18: 163.37 | P18: 113.37 | Q18: 93.37 | R18: 103.37
B19: ='CB-17'!B19 -> TV Cable | C19: =D19 -> 0 | D19: =E19*F19 -> 0 | E19: ='CB-17'!E19 -> 0.5 | F19: =SUM(G19:R19) -> 0
B20: ='CB-17'!B20 -> DEPRECIABLE ASSETS | C20: =SUM(C21:C26) -> 288.95 | G20: =SUM(G21:G26) -> 19.8 | H20: =SUM(H21:H26) -> 0 | I20: =SUM(I21:I26) -> 27.12 | J20: =SUM(J21:J26) -> 72.3 | K20: =SUM(K21:K26) -> 0 | L20: =SUM(L21:L26) -> 0 | M20: =SUM(M21:M26) -> 38.48 | N20: =SUM(N21:N26) -> 0 | ... R20: =SUM(R21:R26) -> 23.16
B21: ='CB-17'!B21 -> ASUS Laptop | C21: =D21 -> 0 | D21: =E21*F21 -> 0 | E21: ='CB-17'!E21 -> 0.5 | F21: =SUM(G21:R21) -> 0
B22: ='CB-17'!B22 -> Mobile Device (samsung) | C22: =D22 -> 94.5 | D22: =E22*F22 -> 94.5 | E22: ='CB-17'!E22 -> 0.5 | F22: =SUM(G22:R22) -> 189 | Q22: =148.6+40.4 -> 189
B23: ='CB-17'!B23 -> Cellphone Device | C23: =D23 -> 0 | D23: =E23*F23 -> 0 | E23: ='CB-17'!E23 -> 0.5
B24: ='CB-17'!B24 -> Supplies | C24: =D24 -> 100.64 | D24: =E24*F24 -> 100.64 | E24: ='CB-17'!E24 -> 1 | F24: =SUM(G24:R24) -> 100.64 | I24: 27.12 | M24: 38.48 | P24: 11.88 | R24: 23.16
B25: ='CB-17'!B25 -> Stationaries | C25: =D25 -> 21.51 | D25: =E25*F25 -> 21.51 | E25: ='CB-17'!E25 -> 1 | F25: =SUM(G25:R25) -> 21.51 | G25: 19.8 | O25: 0.78 | P25: 0.93
B26: ='CB-17'!B26 -> Books | C26: =D26 -> 72.3 | D26: =E26*F26 -> 72.3 | E26: ='CB-17'!E26 -> 1 | F26: =SUM(G26:R26) -> 72.3 | J26: 72.3
B27: ='CB-17'!B27 -> GOVERNMENT FEES | C27: =SUM(C28:C34) -> 242.13 | D27: Prorated | E27: Rate | F27: Annual
B28: ='CB-17'!B28 -> Biz Registration | C28: =D28 -> 0 | D28: =E28*F28 -> 0 | E28: ='CB-17'!E28 -> 1 | F28: =SUM(G28:R28) -> 0
B29: ='CB-18'!B29 -> Licensing | C29: =D29 -> 0 | D29: =E29*F29 -> 0 | E29: ='CB-17'!E29 -> 1 | F29: =SUM(G29:R29) -> 0
B30: ='CB-17'!B30 -> WA DOR Excise Tax | C30: =D30 -> 104 | D30: =E30*F30 -> 104 | E30: ='CB-17'!E30 -> 1 | F30: =SUM(G30:R30) -> 104 | K30: 104
B31: ='CB-17'!B31 -> Garnishment Fee | C31: =D31 -> 0 | D31: =E31*F31 -> 0 | E31: ='CB-17'!E31 -> 1 | F31: =SUM(G31:R31) -> 0
B32: ='CB-17'!B32 -> LNI Insurance | C32: =D32 -> 138.13 | D32: =E32*F32 -> 138.13 | E32: ='CB-17'!E32 -> 1 | F32: =SUM(G32:R32) -> 138.13 | J32: =33.64+84.46 -> 118.1 | K32: 10.03 | P32: 10
B33: ='CB-17'!B33 -> WA Employment Security | C33: =D33 -> 0 | D33: =E33*F33 -> 0 | E33: ='CB-17'!E33 -> 1
B34: ='CB-17'!B34 -> Commercial Insurance | C34: =D34 -> 0 | D34: =E34*F34 -> 0 | E34: ='CB-17'!E34 -> 1
B35: ='CB-17'!B35 -> PROFESSIONAL SERVICES | C35: =SUM(C36:C44) -> 3521.7867
A36: Google | B36: ='CB-17'!B36 -> Web Domains | C36: =D36 -> 237.44 | D36: =E36*F36 -> 237.44 | E36: ='CB-17'!E36 -> 1 | F36: =SUM(G36:R36) -> 237.44 | G36: =33.03+33.03+22.02 -> 88.08 | H36: =13.21+56.88 -> 70.09 | I36: 13.21 | J36: 26.42 | P36: 39.64
A37: godaddy | B37: ='CB-17'!B37 -> Web Hosting | C37: =D37 -> 123.1 | D37: =E37*F37 -> 123.1 | E37: ='CB-17'!E37 -> 1 | F37: =SUM(G37:R37) -> 123.1 | G37: 20.01 | M37: 14.93 | P37: 88.16
A38: google/fb | B38: Digital Ads | C38: =D38 -> 0 | D38: =E38*F38 -> 0 | E38: ='CB-17'!E38 -> 1 | F38: =SUM(G38:R38) -> 0
A39: logo | B39: Logo Services | C39: =D39 -> 0 | D39: =E39*F39 -> 0 | E39: ='CB-17'!E39 -> 1 | F39: =SUM(G39:R39) -> 0
A40: misc. | B40: Temp Services | C40: =D40 -> 2426.6667 | D40: =E40*F40 -> 2426.6667 | E40: ='CB-17'!E40 -> 1 | F40: =(52/3)*140 -> 2426.6667
...

Sheet CB-20
A1: =Summary!J5 -> 2020 | B1: =Summary!J5 -> 2020 | G1: ="CLOUDBAUD CONSULTING "& Summary!J5 & " ONLY" -> CLOUDBAUD CONSULTING 2020 ONLY
A2: Sources | F2: TOTAL | G2: Jan | H2: Feb | I2: Mar | J2: Apr | K2: May | L2: Jun | M2: July | N2: Aug | O2: Sep | P2: Oct | Q2: Nov | R2: Dec
A3: Various | B3: ='CB-17'!B3 -> CONSULTING REVENUE | C3: =F3 -> 0 | F3: =SUM(G3:R3) -> 0 | G3: 0
F4: YTD | G4: =G3 -> 0 | H4: =G4+H3 -> 0 | I4: =H4+I3 -> 0 | J4: =I4+J3 -> 0 | K4: =J4+K3 -> 0 | L4: =K4+L3 -> 0 | M4: =L4+M3 -> 0 | N4: =M4+N3 -> 0 | O4: =N4+O3 -> 0 | ... R4: =Q4+R3 -> 0
B5: ='CB-17'!B5 -> TOTAL EXPENSES | C5: =C7+C20+C27+C76+C35+C59+C45+C62+C67+C71 -> 1569.8499 | F5: =SUM(G5:R5) -> 0
B6: ='CB-17'!B6 -> NET REVENUE | C6: =C3-C5 -> -1569.8499
B7: ='CB-17'!B7 -> UTILITIES | C7: =SUM(C8:C19) -> 809.1099 | D7: Prorated | E7: Rate | F7: Annual | G7: =SUM(H8:H14) -> 429.71 | H7: =SUM(I8:I14) -> 80.67 | I7: =SUM(J8:J14) -> 450.14 | J7: =SUM(K8:K32) -> 385.76 | K7: =SUM(L8:L14) -> 18.16 | L7: =SUM(M8:M14) -> 63.51 | M7: =SUM(N8:N14) -> 393.17 | N7: =SUM(O8:O14) -> 80.86 | O7: =SUM(P8:P14) -> 546.34 | P7: =SUM(Q8:Q14) -> 543.77 | Q7: =SUM(R8:R14) -> 81.38 | R7: =SUM(S8:S14) -> 0 | T7: 3048 | U7: 320.03 | V7: 45066
A8: PSE | B8: ='CB-17'!B8 -> Electricity | C8: =D8 -> 48.8206 | D8: =E8*F8 -> 48.8206 | E8: ='CB-17'!E8 -> 0.17 | F8: =SUM(G8:R8) -> 287.18 | P8: 123.52 | Q8: 163.66
A9: City | B9: ='CB-17'!B9 -> Waste & Recycle | C9: =D9 -> 55.1786 | D9: =E9*F9 -> 55.1786 | E9: ='CB-17'!E9 -> 0.17 | F9: =SUM(G9:R9) -> 324.58 | I9: 80.67 | L9: 18.16 | M9: 63.51 | O9: 80.86 | R9: 81.38
A10: City | B10: ='CB-17'!B10 -> Water & Sewer | C10: =D10 -> 418.4907 | D10: =E10*F10 -> 418.4907 | E10: ='CB-17'!E10 -> 0.17 | F10: =SUM(G10:R10) -> 2461.71 | H10: 429.71 | J10: 450.14 | K10: 385.76 | N10: 393.17 | P10: 422.82 | Q10: 380.11
A11: ADT | B11: ='CB-17'!B11 -> Security | C11: =D11 -> 0 | D11: =E11*F11 -> 0 | E11: ='CB-17'!E11 -> 0.17 | F11: =SUM(G11:R11) -> 0
A12: Personal | B12: ='CB-17'!B12 -> Landscaping | C12: =D12 -> 0 | D12: =E12*F12 -> 0 | E12: ='CB-17'!E12 -> 0.17 | F12: =SUM(G12:R12) -> 0
B13: ='CB-17'!B13 -> Home Owners Insurance | C13: =D13 -> 286.62 | D13: =E13*F13 -> 286.62 | E13: ='CB-17'!E13 -> 0.17 | F13: ='Home Insurance'!I13 -> 1686
A14: ='CB-17'!A14 -> CCMSEARS | B14: ='CB-17'!B14 -> Appliance Maintenance | C14: =D14 -> 0 | D14: =E14*F14 -> 0 | E14: ='CB-17'!E14 -> 0.5 | F14: ='Home Insurance'!I14 -> 0
B15: ='CB-17'!B15 -> Apple Warranty | C15: =D15 -> 0 | D15: =E15*F15 -> 0 | E15: ='CB-17'!E15 -> 0.5 | F15: ='Home Insurance'!I15 -> 0
B16: ='CB-17'!B16 -> Computers Warranty | C16: =D16 -> 0 | D16: =E16*F16 -> 0 | E16: ='CB-17'!E16 -> 0.5 | F16: ='Home Insurance'!I16 -> 0
A17: T-Mobile | B17: ='CB-17'!B17 -> Cellular Service | C17: =D17 -> 0 | D17: =E17*F17 -> 0 | E17: ='CB-17'!E17 -> 0.5 | F17: ='Home Insurance'!I17 -> 0
A18: Comcast | B18: ='CB-17'!B18 -> Broadband | C18: =D18 -> 0 | D18: =E18*F18 -> 0 | E18: ='CB-17'!E18 -> 0.5 | F18: ='Home Insurance'!I18 -> 0
B19: ='CB-17'!B19 -> TV Cable | C19: =D19 -> 0 | D19: =E19*F19 -> 0 | E19: ='CB-17'!E19 -> 0.5 | F19: ='Home Insurance'!I19 -> 0
B20: ='CB-17'!B20 -> DEPRECIABLE ASSETS | C20: =SUM(C21:C26) -> 0 | D20: Prorated | E20: Rate | F20: Annual | G20: =SUM(G21:G26) -> 0 | H20: =SUM(H21:H26) -> 0 | I20: =SUM(I21:I26) -> 0 | J20: =SUM(J21:J26) -> 0 | K20: =SUM(K21:K26) -> 0 | L20: =SUM(L21:L26) -> 0 | M20: =SUM(M21:M26) -> 0 | N20: =SUM(N21:N26) -> 0 | ... R20: =SUM(R21:R26) -> 0
B21: ='CB-17'!B21 -> ASUS Laptop | C21: =D21 -> 0 | D21: =E21*F21 -> 0 | E21: ='CB-17'!E21 -> 0.5 | F21: =SUM(G21:R21) -> 0
B22: ='CB-17'!B22 -> Mobile Device (samsung) | C22: =D22 -> 0 | D22: =E22*F22 -> 0 | E22: ='CB-17'!E22 -> 0.5 | F22: =SUM(G22:R22) -> 0
B23: ='CB-17'!B23 -> Cellphone Device | C23: =D23 -> 0 | D23: =E23*F23 -> 0 | E23: ='CB-17'!E23 -> 0.5 | F23: =SUM(G23:R23) -> 0
B24: ='CB-17'!B24 -> Supplies | C24: =D24 -> 0 | D24: =E24*F24 -> 0 | E24: ='CB-17'!E24 -> 1 | F24: =SUM(G24:R24) -> 0
B25: ='CB-17'!B25 -> Stationaries | C25: =D25 -> 0 | D25: =E25*F25 -> 0 | E25: ='CB-17'!E25 -> 1 | F25: =SUM(G25:R25) -> 0
B26: ='CB-17'!B26 -> Books | C26: =D26 -> 0 | D26: =E26*F26 -> 0 | E26: ='CB-17'!E26 -> 1 | F26: =SUM(G26:R26) -> 0
B27: ='CB-17'!B27 -> GOVERNMENT FEES | C27: =SUM(C28:C34) -> 197.22 | D27: Prorated | E27: Rate | F27: Annual
A28: Olympia + KC + City | B28: ='CB-17'!B28 -> Biz Registration | C28: =D28 -> 0 | D28: =E28*F28 -> 0 | E28: ='CB-17'!E28 -> 1 | F28: =SUM(G28:R28) -> 0
B29: ='CB-17'!B29 -> Licensing | C29: =D29 -> 157.22 | D29: =E29*F29 -> 157.22 | E29: ='CB-17'!E29 -> 1 | F29: =SUM(G29:R29) -> 157.22 | G29: 157.22
B30: ='CB-17'!B30 -> WA DOR Excise Tax | C30: =D30 -> 0 | D30: =E30*F30 -> 0 | E30: ='CB-17'!E30 -> 1 | F30: =SUM(G30:R30) -> 0
B31: ='CB-17'!B31 -> Garnishment Fee | C31: =D31 -> 0 | D31: =E31*F31 -> 0 | E31: ='CB-17'!E31 -> 1 | F31: =SUM(G31:R31) -> 0
B32: ='CB-17'!B32 -> LNI Insurance | C32: =D32 -> 40 | D32: =E32*F32 -> 40 | E32: ='CB-17'!E32 -> 1 | F32: =SUM(G32:R32) -> 40 | I32: 40
B33: ='CB-17'!B33 -> WA Employment Security | C33: =D33 -> 0 | D33: =E33*F33 -> 0 | E33: ='CB-17'!E33 -> 1 | F33: =SUM(G33:R33) -> 0
B34: ='CB-17'!B34 -> Commercial Insurance | C34: =D34 -> 0 | D34: =E34*F34 -> 0 | E34: ='CB-17'!E34 -> 1 | F34: =SUM(G34:R34) -> 0
B35: PROFESSIONAL SERVICES | C35: =SUM(C36:C44) -> 277 | D35: Prorated | E35: Rate | F35: Annual
B36: ='CB-17'!B36 -> Web Domains | C36: =D36 -> 0 | D36: =E36*F36 -> 0 | E36: ='CB-17'!E36 -> 1 | F36: =SUM(G36:R36) -> 0
B37: ='CB-17'!B37 -> Web Hosting | C37: =D37 -> 0 | D37: =E37*F37 -> 0 | E37: ='CB-17'!E37 -> 1 | F37: =SUM(G37:R37) -> 0
B38: ='CB-17'!B38 -> Digital Ads | C38: =D38 -> 0 | D38: =E38*F38 -> 0 | E38: ='CB-17'!E38 -> 1 | F38: =SUM(G38:R38) -> 0
B39: ='CB-17'!B39 -> Logo Services | C39: =D39 -> 0 | D39: =E39*F39 -> 0 | E39: ='CB-17'!E39 -> 1 | F39: =SUM(G39:R39) -> 0
B40: ='CB-17'!B40 -> Temp Services | C40: =D40 -> 0 | D40: =E40*F40 -> 0 | E40: ='CB-17'!E40 -> 1 | F40: =SUM(G40:R40) -> 0
...

Sheet CB-19
B1: =Summary!K5 -> 2019 | C1: =Summary!K5 -> 2019 | H1: ="CLOUDBAUD CONSULTING "& Summary!K5 & " ONLY" -> CLOUDBAUD CONSULTING 2019 ONLY
B2: Sources | G2: TOTAL | H2: Jan | I2: Feb | J2: Mar | K2: Apr | L2: May | M2: Jun | N2: Jul | O2: Aug | P2: Sep | Q2: Oct | R2: Nov | S2: Dec | U2: Check# | V2: Amount | W2: Date | X2: Payee
B3: Various | C3: ='CB-17'!B3 -> CONSULTING REVENUE | D3: =G3 -> 130000 | G3: =SUM(H3:S3) -> 130000 | H3: =10000+10000 -> 20000 | I3: =10000+10000 -> 20000 | J3: =10000+10000 -> 20000 | K3: =10000+10000 -> 20000 | L3: =10000+10000 -> 20000 | M3: =10000+10000 -> 20000 | N3: 0 | O3: 10000 | P3: 0 | Q3: 0 | R3: 0 | S3: 0 | U3: 9923 | V3: 200 | W3: 44944
G4: YTD | H4: =H3 -> 20000 | I4: =H4+I3 -> 40000 | J4: =I4+J3 -> 60000 | K4: =J4+K3 -> 80000 | L4: =K4+L3 -> 100000 | M4: =L4+M3 -> 120000 | N4: =M4+N3 -> 120000 | O4: =N4+O3 -> 130000 | P4: =O4+P3 -> 130000 | ... S4: =R4+S3 -> 130000 | U4: 9924 | V4: 200 | W4: 44977
C5: ='CB-17'!B5 -> TOTAL EXPENSES | D5: =D7+D20+D27+D76+D35+D59+D45+D62+D67+D71 -> 50174.487 | U5: 9925 | V5: 200 | W5: 45004
C6: ='CB-17'!B6 -> NET REVENUE | D6: =D3-D5 -> 79825.513
C7: ='CB-17'!B7 -> UTILITIES | D7: =SUM(D8:D19) -> 1712.8666 | E7: Prorated | F7: Rate | G7: Annual | H7: =SUM(H8:H14) -> 445.12 | I7: =SUM(I8:I14) -> 1217.14 | J7: =SUM(J8:J14) -> 479.18 | K7: =SUM(K8:K34) -> 1736.62 | L7: =SUM(L8:L14) -> 365.36 | M7: =SUM(M8:M14) -> 706.03 | N7: =SUM(N8:N14) -> 332.83 | O7: =SUM(O8:O14) -> 600.07 | P7: =SUM(P8:P14) -> 190 | Q7: =SUM(Q8:Q14) -> 682.43 | R7: =SUM(R8:R14) -> 397.14 | S7: =SUM(S8:S14) -> 1115.94 | U7: 3048 | V7: 320.03 | W7: 45066
B8: =#REF! -> #REF! | C8: ='CB-17'!B8 -> Electricity | D8: =E8 -> 368.8048 | E8: =F8*G8 -> 368.8048 | F8: ='CB-17'!E8 -> 0.17 | G8: =SUM(H8:S8) -> 2169.44 | H8: 255.12 | I8: 272.7 | J8: 289.18 | K8: 249.83 | L8: 175.36 | M8: =12.64+130.19 -> 142.83 | N8: =12.64+130.19 -> 142.83 | O8: 67.14 | Q8: 119.23 | R8: 207.14 | S8: 248.08
B9: =#REF! -> #REF! | C9: ='CB-17'!B9 -> Waste & Recycle | D9: =E9 -> 22.1561 | E9: =F9*G9 -> 22.1561 | F9: ='CB-17'!E9 -> 0.17 | G9: =SUM(H9:S9) -> 130.33 | K9: 130.33
B10: =#REF! -> #REF! | C10: ='CB-17'!B10 -> Water & Sewer | D10: =E10 -> 499.3257 | E10: =F10*G10 -> 499.3257 | F10: ='CB-17'!E10 -> 0.17 | G10: =SUM(H10:S10) -> 2937.21 | I10: 754.44 | K10: 415.58 | M10: 373.2 | O10: 342.93 | Q10: 373.2 | S10: 677.86
B11: =#REF! -> #REF! | C11: ='CB-17'!B11 -> Security | D11: =E11 -> 102 | E11: =F11*G11 -> 102 | F11: ='CB-17'!E11 -> 0.17 | G11: =SUM(H11:S11) -> 600 | H11: 50 | I11: 50 | J11: 50 | K11: 50 | L11: 50 | M11: 50 | N11: 50 | O11: 50 | P11: 50 | Q11: 50 | R11: 50 | S11: 50
B12: =#REF! -> #REF! | C12: ='CB-17'!B12 -> Landscaping | D12: =E12 -> 285.6 | E12: =F12*G12 -> 285.6 | F12: ='CB-17'!E12 -> 0.17 | G12: =SUM(H12:S12) -> 1680 | H12: 140 | I12: 140 | J12: 140 | K12: 140 | L12: 140 | M12: 140 | N12: 140 | O12: 140 | P12: 140 | Q12: 140 | R12: 140 | S12: 140
C13: ='CB-17'!B13 -> Home Owners Insurance | D13: =E13 -> 0 | E13: =F13*G13 -> 0 | F13: ='CB-17'!E13 -> 0.17 | G13: =SUM(H13:S13) -> 0
C14: ='CB-17'!B14 -> Appliance Maintenance | D14: =E14 -> 0 | E14: =F14*G14 -> 0 | F14: ='CB-17'!E14 -> 0.5 | G14: =SUM(H14:S14) -> 0
C15: ='CB-17'!B15 -> Apple Warranty | D15: =E15 -> 164.5 | E15: =F15*G15 -> 164.5 | F15: ='CB-17'!E15 -> 0.5 | G15: =SUM(H15:S15) -> 329 | K15: 329
C16: ='CB-17'!B16 -> Computers Warranty | D16: =E16 -> 0 | E16: =F16*G16 -> 0 | F16: ='CB-17'!E16 -> 0.5 | G16: =SUM(H16:S16) -> 0
B17: T-Mobile | C17: ='CB-17'!B17 -> Cellular Service | D17: =E17 -> 270.48 | E17: =F17*G17 -> 270.48 | F17: ='CB-17'!E17 -> 0.5 | G17: =SUM(H17:S17) -> 540.96 | H17: 45.08 | J17: =45.08+45.08 -> 90.16 | L17: =45.08+45.08 -> 90.16 | N17: =45.08+45.08 -> 90.16 | O17: 45.08 | Q17: =45.08+45.08 -> 90.16 | S17: =45.08+45.08 -> 90.16
A18: xfiniti | B18: Comcast | C18: ='CB-17'!B18 -> Broadband | D18: =E18 -> 0 | E18: =F18*G18 -> 0 | F18: ='CB-17'!E18 -> 0.5 | G18: =SUM(H18:S18) -> 0
C19: ='CB-17'!B19 -> TV Cable | D19: =E19 -> 0 | E19: =F19*G19 -> 0 | F19: ='CB-17'!E19 -> 0.5 | G19: =SUM(H19:S19) -> 0
C20: ='CB-17'!B20 -> DEPRECIABLE ASSETS | D20: =SUM(D21:D26) -> 0 | E20: Prorated | F20: Rate | G20: Annual | H20: =SUM(H21:H26) -> 0 | I20: =SUM(I21:I26) -> 0 | J20: =SUM(J21:J26) -> 0 | K20: =SUM(K21:K26) -> 0 | L20: =SUM(L21:L26) -> 0 | M20: =SUM(M21:M26) -> 0 | N20: =SUM(N21:N26) -> 0 | O20: =SUM(O21:O26) -> 0 | ... S20: =SUM(S21:S26) -> 0
C21: ='CB-17'!B21 -> ASUS Laptop | D21: =E21 -> 0 | E21: =F21*G21 -> 0 | F21: ='CB-17'!E21 -> 0.5 | G21: =SUM(H21:S21) -> 0
C22: ='CB-17'!B22 -> Mobile Device (samsung) | D22: =E22 -> 0 | E22: =F22*G22 -> 0 | F22: ='CB-17'!E22 -> 0.5 | G22: =SUM(H22:S22) -> 0
C23: ='CB-17'!B23 -> Cellphone Device | D23: =E23 -> 0 | E23: =F23*G23 -> 0 | F23: ='CB-17'!E23 -> 0.5 | G23: =SUM(H23:S23) -> 0
C24: ='CB-17'!B24 -> Supplies | D24: =E24 -> 0 | E24: =F24*G24 -> 0 | F24: ='CB-17'!E24 -> 1 | G24: =SUM(H24:S24) -> 0
C25: ='CB-17'!B25 -> Stationaries | D25: =E25 -> 0 | E25: =F25*G25 -> 0 | F25: ='CB-17'!E25 -> 1 | G25: =SUM(H25:S25) -> 0
C26: ='CB-17'!B26 -> Books | D26: =E26 -> 0 | E26: =F26*G26 -> 0 | F26: ='CB-17'!E26 -> 1 | G26: =SUM(H26:S26) -> 0
C27: ='CB-17'!B27 -> GOVERNMENT FEES | D27: =SUM(D28:D34) -> 5015.77 | E27: Prorated | F27: Rate | G27: Annual
B28: =#REF! -> #REF! | C28: ='CB-17'!B28 -> Biz Registration | D28: =G28 -> 0 | E28: =F28*G28 -> 0 | F28: ='CB-17'!E28 -> 1 | G28: =SUM(H28:S28) -> 0
C29: ='CB-18'!B29 -> Licensing | D29: =G29 -> 0 | E29: =F29*G29 -> 0 | F29: ='CB-17'!E29 -> 1 | G29: =SUM(H29:S29) -> 0
C30: ='CB-17'!B30 -> WA DOR Excise Tax | D30: =G30 -> 3838.61 | E30: =F30*G30 -> 3838.61 | F30: ='CB-17'!E30 -> 1 | G30: =SUM(H30:S30) -> 3838.61 | H30: 911.59 | I30: 559.19 | J30: 542.87 | K30: 421.88 | L30: 326.25 | N30: =478.79+517.5 -> 996.29 | R30: 80.54
C31: ='CB-17'!B31 -> Garnishment Fee | D31: =G31 -> 250 | E31: =F31*G31 -> 250 | F31: ='CB-17'!E31 -> 1 | G31: =SUM(H31:S31) -> 250 | H31: 125 | P31: 125
C32: ='CB-17'!B32 -> LNI Insurance | D32: =G32 -> 207.45 | E32: =F32*G32 -> 207.45 | F32: ='CB-17'!E32 -> 1 | G32: =SUM(H32:S32) -> 207.45 | H32: 207.45
C33: ='CB-17'!B33 -> WA Employment Security | D33: =G33 -> 719.71 | E33: =F33*G33 -> 719.71 | F33: ='CB-17'!E33 -> 1 | G33: =SUM(H33:S33) -> 719.71 | P33: 719.71
C34: ='CB-17'!B34 -> Commercial Insurance | D34: =G34 -> 0 | E34: =F34*G34 -> 0 | F34: ='CB-17'!E34 -> 1 | G34: =SUM(H34:S34) -> 0
C35: ='CB-17'!B35 -> PROFESSIONAL SERVICES | D35: =SUM(D36:D44) -> 245.85 | E35: Prorated | F35: Rate | G35: Annual
C36: ='CB-17'!B36 -> Web Domains | D36: =G36 -> 0 | E36: =F36*G36 -> 0 | F36: ='CB-17'!E36 -> 1 | G36: =SUM(H36:S36) -> 0
C37: ='CB-17'!B37 -> Web Hosting | D37: =G37 -> 0 | E37: =F37*G37 -> 0 | F37: ='CB-17'!E37 -> 1 | G37: =SUM(H37:S37) -> 0
C38: ='CB-17'!B38 -> Digital Ads | D38: =G38 -> 0 | E38: =F38*G38 -> 0 | F38: ='CB-17'!E38 -> 1 | G38: =SUM(H38:S38) -> 0
C39: ='CB-17'!B39 -> Logo Services | D39: =G39 -> 0 | E39: =F39*G39 -> 0 | F39: ='CB-17'!E39 -> 1 | G39: =SUM(H39:S39) -> 0
C40: ='CB-17'!B40 -> Temp Services | D40: =G40 -> 0 | E40: =F40*G40 -> 0 | F40: ='CB-17'!E40 -> 1 | G40: =SUM(H40:S40) -> 0
...

Sheet CB-18
A1: =Summary!L5 -> 2018 | B1: =Summary!L5 -> 2018 | G1: ="CLOUDBAUD CONSULTING "& Summary!L5 & " ONLY" -> CLOUDBAUD CONSULTING 2018 ONLY | T1: Last Update | V1: =NOW() -> 45893.328
A2: Sources | C2: ='CB-17'!C2 -> 0 | D2: ='CB-17'!D2 -> 0 | F2: TOTAL | G2: Jan | H2: Feb | I2: Mar | J2: Apr | K2: May | L2: Jun | M2: Jul | N2: Aug | O2: Sep | P2: Oct | Q2: Nov | R2: Dec | T2: Check# | U2: Amount | V2: Date | W2: Payee
A3: Various | B3: ='CB-17'!B3 -> CONSULTING REVENUE | C3: =F3-D3 -> 485019.41 | F3: =SUM(G3:R3) -> 485019.41 | G3: =15630+15630 -> 31260 | H3: =18018.79+H4-G4-18018.79 -> 35898.79 | I3: =I4-H4 -> 33883.57 | J3: =J4-I4 -> 33702.5 | K3: =16735+16927.7 -> 33662.7 | L3: =L4-K4 -> 33682.7 | M3: =M4-L4 -> 48414.56 | N3: =N4-M4 -> 40082.7 | O3: =O4-N4 -> 51282.7 | P3: =P4-O4 -> 51282.7 | Q3: =Q4-P4 -> 44923.57 | R3: =23130+10000+13812.92 -> 46942.92 | T3: 3032 | U3: 19 | V3: jan | W3: DOR
F4: YTD | G4: =G3 -> 31260 | H4: =67158.79 -> 67158.79 | I4: 101042.36 | J4: =K4-K3 -> 134744.86 | K4: 168407.56 | L4: 202090.26 | M4: 250504.82 | N4: 290587.52 | O4: 341870.22 | P4: 393152.92 | Q4: 438076.49 | R4: =461206.49+23812.92 -> 485019.41 | T4: 3033 | U4: 500 | V4: jan | W4: Edilberto
B5: ='CB-17'!B5 -> TOTAL EXPENSES | C5: =C7+C20+C27+C76+C35+C59+C45+C62+C67+C71 -> #REF! | D5: =SUM(D8:D18) -> 3612.6345 | T5: 3034 | U5: 1269 | V5: jan | W5: Deepika
B6: ='CB-17'!B6 -> NET REVENUE | C6: =C3-C5 -> #REF! | T6: 3035 | U6: 1000 | V6: jan | W6: edilberto
A7: PSE | B7: ='CB-17'!B7 -> UTILITIES | C7: =SUM(C8:C19) -> 3612.6345 | D7: Prorated | E7: Rate | F7: Annual | G7: =SUM(G8:G14) -> 490 | H7: =SUM(H8:H14) -> 841.33 | I7: =SUM(I8:I14) -> 490 | J7: =SUM(J8:J14) -> 840.86 | K7: =SUM(K8:K14) -> 490 | L7: =SUM(L8:L14) -> 988.88 | M7: =SUM(M8:M14) -> 2269.83 | N7: =SUM(N8:N14) -> 992.06 | ... R7: =SUM(R8:R14) -> 1194.96 | T7: 3036 | U7: 500 | V7: jan | W7: edilberto
A8: City | B8: ='CB-17'!B8 -> Electricity | C8: =D8 -> 152.6991 | D8: =E8*F8 -> 152.6991 | E8: ='CB-17'!E8 -> 0.17 | F8: =SUM(G8:R8) -> 898.23 | G8: 0 | H8: 0 | I8: 0 | J8: 0 | K8: 0 | L8: =12.64+130.19 -> 142.83 | M8: =12.64+130.19 -> 142.83 | N8: =8.7+111.68 -> 120.38 | O8: 120.89 | P8: 0 | Q8: 61.65 | R8: =95.6+214.05 -> 309.65 | T8: 3577 | U8: 300 | V8: jan | W8: SEARS
A9: City | B9: ='CB-17'!B9 -> Waste & Recycle | C9: =D9 -> 0 | D9: =E9*F9 -> 0 | E9: ='CB-17'!E9 -> 0.17 | F9: =SUM(G9:R9) -> 0 | G9: 0 | H9: 0 | I9: 0 | J9: 0 | K9: 0 | L9: 0 | M9: 0 | N9: 0 | O9: 0 | P9: 0 | Q9: 0 | R9: 0 | T9: 9910 | U9: 135 | V9: jan | W9: BoA
A10: ADT | B10: ='CB-17'!B10 -> Water & Sewer | C10: =D10 -> 384.9854 | D10: =E10*F10 -> 384.9854 | E10: ='CB-17'!E10 -> 0.17 | F10: =SUM(G10:R10) -> 2264.62 | H10: 351.33 | I10: 0 | J10: 350.86 | K10: 0 | L10: 356.05 | M10: 0 | N10: 381.68 | O10: 0 | P10: 429.39 | Q10: 0 | R10: 395.31 | T10: 9911 | U10: 135 | V10: jan | W10: BoA
A11: Personal | B11: ='CB-17'!B11 -> Security | C11: =D11 -> 102 | D11: =E11*F11 -> 102 | E11: ='CB-17'!E11 -> 0.17 | F11: =SUM(G11:R11) -> 600 | G11: 50 | H11: 50 | I11: 50 | J11: 50 | K11: 50 | L11: 50 | M11: 50 | N11: 50 | O11: 50 | P11: 50 | Q11: 50 | R11: 50 | T11: 3011 | U11: 2000 | V11: feb
B12: ='CB-17'!B12 -> Landscaping | C12: =D12 -> 285.6 | D12: =E12*F12 -> 285.6 | E12: ='CB-17'!E12 -> 0.17 | F12: =SUM(G12:R12) -> 1680 | G12: 140 | H12: 140 | I12: 140 | J12: 140 | K12: 140 | L12: 140 | M12: 140 | N12: 140 | O12: 140 | P12: 140 | Q12: 140 | R12: 140 | T12: 3578 | U12: 300 | V12: feb | W12: SEARS
A13: CCMSEARS | B13: ='CB-17'!B13 -> Home Owners Insurance | C13: =D13 -> 278.29 | D13: =E13*F13 -> 278.29 | E13: ='CB-17'!E13 -> 0.17 | F13: =SUM(G13:R13) -> 1637 | G13: 0 | H13: 0 | I13: 0 | J13: 0 | K13: 0 | L13: 0 | M13: ='Home Insurance'!K13 -> 1637 | N13: 0 | O13: 0 | P13: 0 | Q13: 0 | R13: 0 | T13: 3012 | U13: 1848.58 | V13: 44646 | W13: Plumbing
B14: ='CB-17'!B14 -> Appliance Maintenance | C14: =D14 -> 1800 | D14: =E14*F14 -> 1800 | E14: ='CB-17'!E14 -> 0.5 | F14: =SUM(G14:R14) -> 3600 | G14: =U8 -> 300 | H14: =U12 -> 300 | I14: =U12 -> 300 | J14: =U22 -> 300 | K14: =U28 -> 300 | L14: 300 | M14: =U35 -> 300 | N14: =U41 -> 300 | O14: 300 | P14: 300 | Q14: 300 | R14: 300
B15: ='CB-17'!B15 -> Apple Warranty | C15: =D15 -> 0 | D15: =E15*F15 -> 0 | E15: ='CB-17'!E15 -> 0.5 | F15: =SUM(G15:R15) -> 0
B16: ='CB-17'!B16 -> Computers Warranty | C16: =D16 -> 0 | D16: =E16*F16 -> 0 | E16: ='CB-17'!E16 -> 0.5 | F16: =SUM(G16:R16) -> 0 | T16: 9912 | U16: 135 | V16: 44621 | W16: BoA
A17: Comcast | B17: ='CB-17'!B17 -> Cellular Service | C17: =D17 -> 609.06 | D17: =F17*E17 -> 609.06 | E17: ='CB-17'!E17 -> 0.5 | F17: =SUM(G17:R17) -> 1218.12 | H17: 305.35 | K17: 126.68 | L17: 172.08 | M17: 172.08 | N17: 117.72 | O17: 112.72 | P17: 112.17 | Q17: 77.43 | R17: 21.89 | T17: 9913 | U17: 135 | V17: 44643 | W17: BoA
B18: ='CB-17'!B18 -> Broadband | C18: =D18 -> 0 | D18: =E18*F18 -> 0 | E18: ='CB-17'!E18 -> 0.5 | F18: =SUM(G18:R18) -> 0 | T18: 3013 | U18: 694 | V18: 44654 | W18: Edilberto
B19: ='CB-17'!B19 -> TV Cable | C19: =D19 -> 0 | D19: =E19*F19 -> 0 | E19: ='CB-17'!E19 -> 0.5 | F19: =SUM(G19:R19) -> 0 | T19: 3014 | U19: 3100 | V19: 44669 | W19: concrete
B20: ='CB-17'!B20 -> DEPRECIABLE ASSETS | C20: =SUM(C21:C26) -> 0 | D20: Prorated | E20: Rate | F20: Annual | G20: =SUM(G21:G26) -> 0 | H20: =SUM(H21:H26) -> 0 | I20: =SUM(I21:I26) -> 0 | J20: =SUM(J21:J26) -> 0 | K20: =SUM(K21:K26) -> 0 | L20: =SUM(L21:L26) -> 0 | M20: =SUM(M21:M26) -> 0 | N20: =SUM(N21:N26) -> 0 | ... R20: =SUM(R21:R26) -> 0 | T20: 3037 | U20: 1000 | V20: 44656 | W20: bathroom
B21: ='CB-17'!B21 -> ASUS Laptop | C21: =F21 -> 0 | D21: =E21*F21 -> 0 | E21: ='CB-17'!E21 -> 0.5 | F21: =SUM(G21:R21) -> 0 | T21: 3038 | U21: 300 | V21: 44662 | W21: paint
A22: Olympia + KC + City | B22: ='CB-17'!B22 -> Mobile Device (samsung) | C22: =F22 -> 0 | D22: =E22*F22 -> 0 | E22: ='CB-17'!E22 -> 0.5 | F22: =SUM(G22:R22) -> 0 | T22: 3580 | U22: 300 | V22: 44654 | W22: SEARS
B23: ='CB-17'!B23 -> Cellphone Device | C23: =F23 -> 0 | D23: =E23*F23 -> 0 | E23: ='CB-17'!E23 -> 0.5 | F23: =SUM(G23:R23) -> 0 | T23: 9914 | U23: 200 | V23: 44669 | W23: BoA
B24: ='CB-17'!B24 -> Supplies | C24: =F24 -> 0 | D24: =E24*F24 -> 0 | E24: 1 | F24: =SUM(G24:R24) -> 0 | T24: 3015 | U24: 200 | V24: 44683
B25: Stationaries | C25: =F25 -> 0 | D25: =E25*F25 -> 0 | E25: 1 | F25: =SUM(G25:R25) -> 0 | T25: 3017 | U25: 900 | V25: 44688 | W25: hector hickman
B26: ='CB-17'!B26 -> Books | C26: =F26 -> 0 | D26: =E26*F26 -> 0 | E26: 1 | F26: =SUM(G26:R26) -> 0 | T26: 3018 | U26: 925 | V26: 44688 | W26: hector hickman
B27: ='CB-17'!B27 -> GOVERNMENT FEES | C27: =SUM(C28:C34) -> 11572.2 | D27: Prorated | E27: Rate | F27: Annual | G27: =SUM(G28:G34) -> 19 | H27: =SUM(H28:H34) -> 0 | I27: =SUM(I28:I34) -> 511.1 | J27: =SUM(J28:J34) -> 0 | K27: =SUM(K28:K34) -> 1746.69 | L27: =SUM(L28:L34) -> 4316.97 | M27: =SUM(M28:M34) -> 0 | N27: =SUM(N28:N34) -> 676.67 | ... R27: =SUM(R28:R34) -> 673.85 | T27: 3039 | U27: 108 | V27: 44712 | W27: Plumbing
B28: ='CB-17'!B28 -> Biz Registration | C28: =F28 -> 0 | D28: =E28*F28 -> 0 | E28: ='CB-17'!E28 -> 1 | F28: =SUM(G28:R28) -> 0 | T28: 3581 | U28: 300 | V28: 44684 | W28: SEARS
B29: ='CB-17'!B29 -> Licensing | C29: =F29 -> 0 | D29: =E29*F29 -> 0 | E29: ='CB-17'!E29 -> 1 | F29: =SUM(G29:R29) -> 0 | T29: 9915 | U29: 200 | V29: 44699 | W29: BoA
B30: ='CB-17'!B30 -> WA DOR Excise Tax | C30: =F30 -> 11572.2 | D30: =E30*F30 -> 11572.2 | E30: ='CB-17'!E30 -> 1 | F30: =SUM(G30:R30) -> 11572.2 | G30: =U3 -> 19 | I30: 511.1 | K30: =854.49+892.2 -> 1746.69 | L30: =538.48+550.38+551.04+604.82+U30 -> 4316.97 | N30: =125.97+550.7 -> 676.67 | Q30: =715.48+838.47+1264.37+769.24+40.36 -> 3627.92 | R30: =673.85 -> 673.85 | T30: 3019 | U30: 2072.25 | V30: 44733 | W30: king county treasury
B31: ='CB-17'!B31 -> Garnishment Fee | C31: =F31 -> 0 | D31: =E31*F31 -> 0 | E31: ='CB-17'!E31 -> 1 | F31: =SUM(G31:R31) -> 0 | T31: 3020 | U31: 206 | V31: 44732 | W31: Edilberto
B32: ='CB-17'!B32 -> LNI Insurance | C32: =F32 -> 0 | D32: =E32*F32 -> 0 | E32: ='CB-17'!E32 -> 1 | F32: =SUM(G32:R32) -> 0 | T32: 3040 | U32: 400 | V32: 44716 | W32: Edilberto
B33: ='CB-17'!B33 -> WA Employment Security | C33: =F33 -> 0 | D33: =E33*F33 -> 0 | E33: ='CB-17'!E33 -> 1 | F33: =SUM(G33:R33) -> 0 | T33: 3041 | U33: 433 | V33: 44718 | W33: Edilberto
B34: ='CB-17'!B34 -> Commercial Insurance | C34: =F34 -> 0 | D34: =E34*F34 -> 0 | E34: ='CB-17'!E34 -> 1 | F34: =SUM(G34:R34) -> 0 | T34: 3042 | U34: 300 | V34: 44723 | W34: Edilberto
B35: ='CB-17'!B35 -> PROFESSIONAL SERVICES | C35: =SUM(C36:C44) -> 875 | D35: Prorated | E35: ='CB-17'!E35 -> Rate | F35: Annual | G35: =SUM(G36:G44) -> 0 | H35: =SUM(H36:H44) -> 0 | I35: =SUM(I36:I44) -> 105 | J35: =SUM(J36:J44) -> 0 | K35: =SUM(K36:K44) -> 47.5 | L35: =SUM(L36:L44) -> 122.5 | M35: =SUM(M36:M44) -> 0 | N35: =SUM(N36:N44) -> 0 | ... R35: =SUM(R36:R44) -> 0 | T35: 3583 | U35: 300 | V35: 44745 | W35: SEARS
A36: GoDaddy | B36: ='CB-17'!B36 -> Web Domains | C36: =F36 -> 0 | D36: =E36*F36 -> 0 | E36: ='CB-17'!E36 -> 1 | F36: =SUM(G36:R36) -> 0 | T36: 9917 | U36: 200 | V36: 44760 | W36: BoA
A37: Comcast | B37: ='CB-17'!B37 -> Web Hosting | C37: =F37 -> 0 | D37: =E37*F37 -> 0 | E37: ='CB-17'!E37 -> 1 | F37: =SUM(G37:R37) -> 0 | T37: 3022 | U37: 570 | V37: 44779 | W37: Edilberto
B38: ='CB-17'!B38 -> Digital Ads | C38: =F38 -> 0 | D38: =E38*F38 -> 0 | E38: ='CB-17'!E38 -> 1 | F38: =SUM(G38:R38) -> 0 | T38: 3023 | U38: 350 | V38: 44779 | W38: Edilberto
B39: ='CB-17'!B39 -> Logo Services | C39: =F39 -> 0 | D39: =E39*F39 -> 0 | E39: ='CB-17'!E39 -> 1 | F39: =SUM(G39:R39) -> 0 | T39: 3024 | U39: 151 | V39: 44794 | W39: Edilberto
B40: ='CB-17'!B40 -> Temp Services | C40: =F40 -> 0 | D40: =E40*F40 -> 0 | E40: ='CB-17'!E40 -> 1 | F40: =SUM(G40:R40) -> 0 | T40: 3025 | U40: 180 | V40: 44794 | W40: Edilberto
...

Sheet CB-17
A1: =Summary!M5 -> 2017 | B1: =Summary!M5 -> 2017 | G1: ="CLOUDBAUD CONSULTING "& Summary!M5 & " ONLY" -> CLOUDBAUD CONSULTING 2017 ONLY
A2: Sources | F2: TOTAL | G2: Jan | H2: Feb | I2: Mar | J2: Apr | K2: May | L2: Jun | M2: July | N2: Aug | O2: Sep | P2: Oct | Q2: Nov | R2: Dec
A3: Various | B3: CONSULTING REVENUE | C3: =F3 -> 335686.39 | F3: =SUM(G3:R3) -> 335686.39 | G3: 0 | H3: 14642.86 | I3: 15000 | J3: 15000 | K3: 15000 | L3: 19276.36 | M3: 45348.54 | N3: 43020 | O3: 51406.16 | P3: 43020 | Q3: 42616.56 | R3: 31355.91
F4: YTD | G4: =G3 -> 0 | H4: =G4+H3 -> 14642.86 | I4: =H4+I3 -> 29642.86 | J4: =I4+J3 -> 44642.86 | K4: =J4+K3 -> 59642.86 | L4: =K4+L3 -> 78919.22 | M4: =L4+M3 -> 124267.76 | N4: =M4+N3 -> 167287.76 | O4: =N4+O3 -> 218693.92 | ... R4: =Q4+R3 -> 335686.39
B5: TOTAL EXPENSES | C5: =C7+C20+C27+C76+C35+C59+C45+C62+C67+C71 -> 1120.9717
B6: NET REVENUE | C6: =C3-C5 -> 334565.42
B7: UTILITIES | C7: =SUM(C8:C19) -> 448.9717 | D7: Prorated | E7: Rate | F7: Annual | G7: =SUM(G8:G19) -> 350.31 | H7: =SUM(H8:H19) -> 238.3 | I7: =SUM(I8:I19) -> 189.33 | J7: =SUM(J8:J19) -> 236.92 | K7: =SUM(K8:K19) -> 105.99 | L7: =SUM(L8:L19) -> 91.06 | M7: =SUM(M8:M19) -> 88.44 | N7: =SUM(N8:N19) -> 210.4 | ... R7: =SUM(R8:R19) -> 313.56
A8: PSE | B8: Electricity | C8: =D8 -> 380.358 | D8: =E8*F8 -> 380.358 | E8: 0.17 | F8: =SUM(G8:R8) -> 2237.4 | G8: 276.41 | H8: 238.3 | I8: 189.33 | J8: 144.27 | K8: 105.99 | L8: 91.06 | M8: 88.44 | N8: 109.39 | O8: 175.01 | P8: 230.13 | Q8: 275.51 | R8: 313.56
A9: City | B9: Waste & Recycle | C9: =D9 -> 68.6137 | D9: =E9*F9 -> 68.6137 | E9: 0.17 | F9: =SUM(G9:R9) -> 403.61 | G9: 73.9 | J9: 92.65 | N9: 101.01 | O9: 61.37 | P9: 74.68
A10: City | B10: Water & Sewer | C10: =D10 -> 0 | D10: =E10*F10 -> 0 | E10: 0.17 | F10: =SUM(G10:R10) -> 0
A11: ADT | B11: Security | C11: =D11 -> 0 | D11: =E11*F11 -> 0 | E11: 0.17 | F11: =SUM(G11:R11) -> 0
A12: Personal | B12: Landscaping | C12: =D12 -> 0 | D12: =E12*F12 -> 0 | E12: 0.17 | F12: =SUM(G12:R12) -> 0
B13: Home Owners Insurance | C13: =D13 -> 0 | D13: =E13*F13 -> 0 | E13: 0.17 | F13: =SUM(G13:R13) -> 0
A14: CCMSEARS | B14: Appliance Maintenance | C14: =D14 -> 0 | D14: =E14*F14 -> 0 | E14: 0.5 | F14: =SUM(G14:R14) -> 0
B15: Apple Warranty | C15: =D15 -> 0 | D15: =E15*F15 -> 0 | E15: 0.5 | F15: =SUM(G15:R15) -> 0
B16: Computers Warranty | C16: =D16 -> 0 | D16: =E16*F16 -> 0 | E16: 0.5 | F16: =SUM(G16:R16) -> 0
A17: T-Mobile | B17: Cellular Service | C17: =D17 -> 0 | D17: =E17*F17 -> 0 | E17: 0.5 | F17: =SUM(G17:R17) -> 0
A18: Comcast | B18: Broadband | C18: =D18 -> 0 | D18: =E18*F18 -> 0 | E18: 0.5 | F18: =SUM(G18:R18) -> 0
B19: TV Cable | C19: =D19 -> 0 | D19: =E19*F19 -> 0 | E19: 0.5 | F19: =SUM(G19:R19) -> 0
B20: DEPRECIABLE ASSETS | C20: =SUM(C21:C26) -> 0 | D20: Prorated | E20: Rate | F20: Annual | G20: =SUM(G21:G26) -> 0 | H20: =SUM(H21:H26) -> 0 | I20: =SUM(I21:I26) -> 0 | J20: =SUM(J21:J26) -> 0 | K20: =SUM(K21:K26) -> 0 | L20: =SUM(L21:L26) -> 0 | M20: =SUM(M21:M26) -> 0 | N20: =SUM(N21:N26) -> 0 | ... R20: =SUM(R21:R26) -> 0
B21: ASUS Laptop | C21: =D21 -> 0 | D21: =E21*F21 -> 0 | E21: 0.5 | F21: =SUM(G21:R21) -> 0
B22: Mobile Device (samsung) | C22: =D22 -> 0 | D22: =E22*F22 -> 0 | E22: 0.5 | F22: =SUM(G22:R22) -> 0
B23: Cellphone Device | C23: =D23 -> 0 | D23: =E23*F23 -> 0 | E23: 0.5 | F23: =SUM(G23:R23) -> 0
B24: Supplies | C24: =D24 -> 0 | D24: =E24*F24 -> 0 | E24: 1 | F24: =SUM(G24:R24) -> 0
B25: ='CB-18'!B25 -> Stationaries | C25: =D25 -> 0 | D25: =E25*F25 -> 0 | E25: 1 | F25: =SUM(G25:R25) -> 0
B26: Books | C26: =D26 -> 0 | D26: =E26*F26 -> 0 | E26: 1 | F26: =SUM(G26:R26) -> 0
B27: GOVERNMENT FEES | C27: =SUM(C28:C34) -> 0 | D27: Prorated | E27: Rate | F27: Annual | G27: =SUM(G28:G34) -> 0 | H27: =SUM(H28:H34) -> 0 | I27: =SUM(I28:I34) -> 0 | J27: =SUM(J28:J34) -> 0 | K27: =SUM(K28:K34) -> 0 | L27: =SUM(L28:L34) -> 0 | M27: =SUM(M28:M34) -> 0 | N27: =SUM(N28:N34) -> 0 | ... T27: =SUM(T28:T34) -> 0
A28: Olympia + KC + City | B28: Biz Registration | C28: =D28 -> 0 | D28: =E28*F28 -> 0 | E28: 1 | F28: =SUM(G28:R28) -> 0
A29: DOL | B29: Licensing | C29: =D29 -> 0 | D29: =E29*F29 -> 0 | E29: 1 | F29: =SUM(G29:R29) -> 0
B30: WA DOR Excise Tax | C30: =D30 -> 0 | D30: =E30*F30 -> 0 | E30: 1 | F30: =SUM(G30:R30) -> 0
B31: Garnishment Fee | C31: =D31 -> 0 | D31: =E31*F31 -> 0 | E31: 1 | F31: =SUM(G31:R31) -> 0
B32: LNI Insurance | C32: =D32 -> 0 | D32: =E32*F32 -> 0 | E32: 1 | F32: =SUM(G32:R32) -> 0
B33: WA Employment Security | C33: =D33 -> 0 | D33: =E33*F33 -> 0 | E33: 1 | F33: =SUM(G33:R33) -> 0
B34: Commercial Insurance | C34: =D34 -> 0 | D34: =E34*F34 -> 0 | E34: 1 | F34: =SUM(G34:R34) -> 0
B35: PROFESSIONAL SERVICES | C35: =SUM(C36:C44) -> 0 | D35: Prorated | E35: Rate | F35: Annual | G35: =SUM(G36:G44) -> 0 | H35: =SUM(H36:H44) -> 0 | I35: =SUM(I36:I44) -> 0 | J35: =SUM(J36:J44) -> 0 | K35: =SUM(K36:K44) -> 0 | L35: =SUM(L36:L44) -> 0 | M35: =SUM(M36:M44) -> 0 | N35: =SUM(N36:N44) -> 0 | ... R35: =SUM(R36:R44) -> 0
B36: Web Domains | C36: =D36 -> 0 | D36: =E36*F36 -> 0 | E36: 1 | F36: =SUM(G36:R36) -> 0
A37: GoDaddy | B37: Web Hosting | C37: =D37 -> 0 | D37: =E37*F37 -> 0 | E37: 1 | F37: =SUM(G37:R37) -> 0
B38: Digital Ads | C38: =D38 -> 0 | D38: =E38*F38 -> 0 | E38: 1 | F38: =SUM(G38:R38) -> 0
B39: Logo Services | C39: =D39 -> 0 | D39: =E39*F39 -> 0 | E39: 1 | F39: =SUM(G39:R39) -> 0
B40: Temp Services | C40: =D40 -> 0 | D40: =E40*F40 -> 0 | E40: 1 | F40: =SUM(G40:R40) -> 0
...

Sheet CC-24
C1: =Summary!G5 -> 2023 | G1: ="CHERRY CREST RENTAL " & C1 &" ONLY" -> CHERRY CREST RENTAL 2023 ONLY
F2: TOTAL | G2: Jan | H2: Feb | I2: Mar | J2: Apr | K2: May | L2: Jun | M2: July | N2: Aug | O2: Sep | P2: Oct | Q2: Nov | R2: Dec
C3: 1099 Revenue | F3: 26760 | G3: =$F$3/12 -> 2230 | H3: =$F$3/12 -> 2230 | I3: =$F$3/12 -> 2230 | J3: =$F$3/12 -> 2230 | K3: =$F$3/12 -> 2230 | L3: =$F$3/12 -> 2230 | M3: =$F$3/12 -> 2230 | N3: =$F$3/12 -> 2230 | ... R3: =$F$3/12 -> 2230
C5: Total Expenses | F5: =SUM(G5:R5) -> 5012.04 | G5: =SUM(G6:G22) -> 417.67 | H5: =SUM(H6:H22) -> 417.67 | I5: =SUM(I6:I22) -> 417.67 | J5: =SUM(J6:J22) -> 417.67 | K5: =SUM(K6:K22) -> 417.67 | L5: =SUM(L6:L22) -> 417.67 | M5: =SUM(M6:M22) -> 417.67 | N5: =SUM(N6:N22) -> 417.67 | ... R5: =SUM(R6:R22) -> 417.67
C6: Mortgage Interest | F6: =SUM(G6:R6) -> 0 | G6: 0 | H6: 0 | I6: 0 | J6: 0 | K6: 0 | L6: 0 | M6: 0 | N6: 0 | O6: 0 | P6: 0 | Q6: 0 | R6: 0
C7: Real-estate Taxes | F7: =SUM(G7:R7) -> 0
C8: Home Owners Insurance | F8: =SUM(G8:R8) -> 0
C9: HOA | F9: =SUM(G9:R9) -> 5012.04 | G9: 417.67 | H9: 417.67 | I9: 417.67 | J9: 417.67 | K9: 417.67 | L9: 417.67 | M9: 417.67 | N9: 417.67 | O9: 417.67 | P9: 417.67 | Q9: 417.67 | R9: 417.67
C10: Appliance Maintenance | F10: =SUM(G10:R10) -> 0
C11: Property Management | F11: =SUM(G11:R11) -> 0
C13: ELECTRICITY | F13: =SUM(G13:R13) -> 0
C14: WASTE | F14: =SUM(G14:R14) -> 0
C15: Water & Sewer | F15: =SUM(G15:R15) -> 0
C16: Security | F16: =SUM(G16:R16) -> 0
B17: xfiniti | C17: BROADBAND | F17: =SUM(G17:R17) -> 0
C19: Landscaping | F19: =SUM(G19:R19) -> 0
C20: Supplies | F20: =SUM(G20:R20) -> 0
B21: misc. | C21: Temp Services | F21: =SUM(G21:R21) -> 0
C22: Bank Fees | F22: =SUM(G22:R22) -> 0
C24: Flooring
C25: Paint
C26: bathroom
C27: electrical work | F27: =SUM(G27:R27) -> 0
C30: Gross Income | F30: =F3-F5 -> 21747.96

Sheet CC-23
C1: =Summary!G5 -> 2023 | G1: ="CHERRY CREST RENTAL " & C1 &" ONLY" -> CHERRY CREST RENTAL 2023 ONLY
F2: TOTAL | G2: Jan | H2: Feb | I2: Mar | J2: Apr | K2: May | L2: Jun | M2: July | N2: Aug | O2: Sep | P2: Oct | Q2: Nov | R2: Dec
C3: 1099 Revenue | F3: 26760 | G3: =$F$3/12 -> 2230 | H3: =$F$3/12 -> 2230 | I3: =$F$3/12 -> 2230 | J3: =$F$3/12 -> 2230 | K3: =$F$3/12 -> 2230 | L3: =$F$3/12 -> 2230 | M3: =$F$3/12 -> 2230 | N3: =$F$3/12 -> 2230 | ... R3: =$F$3/12 -> 2230
C5: Total Expenses | F5: =SUM(G5:R5) -> 5012.04 | G5: =SUM(G6:G22) -> 417.67 | H5: =SUM(H6:H22) -> 417.67 | I5: =SUM(I6:I22) -> 417.67 | J5: =SUM(J6:J22) -> 417.67 | K5: =SUM(K6:K22) -> 417.67 | L5: =SUM(L6:L22) -> 417.67 | M5: =SUM(M6:M22) -> 417.67 | N5: =SUM(N6:N22) -> 417.67 | ... R5: =SUM(R6:R22) -> 417.67
C6: Mortgage Interest | F6: =SUM(G6:R6) -> 0 | G6: 0 | H6: 0 | I6: 0 | J6: 0 | K6: 0 | L6: 0 | M6: 0 | N6: 0 | O6: 0 | P6: 0 | Q6: 0 | R6: 0
C7: Real-estate Taxes | F7: =SUM(G7:R7) -> 0
C8: Home Owners Insurance | F8: =SUM(G8:R8) -> 0
C9: HOA | F9: =SUM(G9:R9) -> 5012.04 | G9: 417.67 | H9: 417.67 | I9: 417.67 | J9: 417.67 | K9: 417.67 | L9: 417.67 | M9: 417.67 | N9: 417.67 | O9: 417.67 | P9: 417.67 | Q9: 417.67 | R9: 417.67
C10: Appliance Maintenance | F10: =SUM(G10:R10) -> 0
C11: Property Management | F11: =SUM(G11:R11) -> 0
C13: ELECTRICITY | F13: =SUM(G13:R13) -> 0
C14: WASTE | F14: =SUM(G14:R14) -> 0
C15: Water & Sewer | F15: =SUM(G15:R15) -> 0
C16: Security | F16: =SUM(G16:R16) -> 0
B17: xfiniti | C17: BROADBAND | F17: =SUM(G17:R17) -> 0
C19: Landscaping | F19: =SUM(G19:R19) -> 0
C20: Supplies | F20: =SUM(G20:R20) -> 0
B21: misc. | C21: Temp Services | F21: =SUM(G21:R21) -> 0
C22: Bank Fees | F22: =SUM(G22:R22) -> 0
C24: Flooring
C25: Paint
C26: bathroom
C27: electrical work | F27: =SUM(G27:R27) -> 0
C30: Gross Income | F30: =F3-F5 -> 21747.96

Sheet CC-22
C1: =Summary!H5 -> 2022 | G1: ="CHERRY CREST RENTAL " & C1 &" ONLY" -> CHERRY CREST RENTAL 2022 ONLY
F2: TOTAL | G2: Jan | H2: Feb | I2: Mar | J2: Apr | K2: May | L2: Jun | M2: July | N2: Aug | O2: Sep | P2: Oct | Q2: Nov | R2: Dec
C3: 1099 Revenue | F3: 26760 | G3: =$F$3/12 -> 2230 | H3: =$F$3/12 -> 2230 | I3: =$F$3/12 -> 2230 | J3: =$F$3/12 -> 2230 | K3: =$F$3/12 -> 2230 | L3: =$F$3/12 -> 2230 | M3: =$F$3/12 -> 2230 | N3: =$F$3/12 -> 2230 | ... R3: =$F$3/12 -> 2230
C5: Total Expenses | F5: =SUM(G5:R5) -> 5012.04 | G5: =SUM(G6:G22) -> 417.67 | H5: =SUM(H6:H22) -> 417.67 | I5: =SUM(I6:I22) -> 417.67 | J5: =SUM(J6:J22) -> 417.67 | K5: =SUM(K6:K22) -> 417.67 | L5: =SUM(L6:L22) -> 417.67 | M5: =SUM(M6:M22) -> 417.67 | N5: =SUM(N6:N22) -> 417.67 | ... R5: =SUM(R6:R22) -> 417.67
C6: Mortgage Interest | F6: =SUM(G6:R6) -> 0 | G6: 0 | H6: 0 | I6: 0 | J6: 0 | K6: 0 | L6: 0 | M6: 0 | N6: 0 | O6: 0 | P6: 0 | Q6: 0 | R6: 0
C7: Real-estate Taxes | F7: =SUM(G7:R7) -> 0
C8: Home Owners Insurance | F8: =SUM(G8:R8) -> 0
C9: HOA | F9: =SUM(G9:R9) -> 5012.04 | G9: 417.67 | H9: 417.67 | I9: 417.67 | J9: 417.67 | K9: 417.67 | L9: 417.67 | M9: 417.67 | N9: 417.67 | O9: 417.67 | P9: 417.67 | Q9: 417.67 | R9: 417.67
C10: Appliance Maintenance | F10: =SUM(G10:R10) -> 0
C11: Property Management | F11: =SUM(G11:R11) -> 0
C13: ELECTRICITY | F13: =SUM(G13:R13) -> 0
C14: WASTE | F14: =SUM(G14:R14) -> 0
C15: Water & Sewer | F15: =SUM(G15:R15) -> 0
C16: Security | F16: =SUM(G16:R16) -> 0
B17: xfiniti | C17: BROADBAND | F17: =SUM(G17:R17) -> 0
C19: Landscaping | F19: =SUM(G19:R19) -> 0
C20: Supplies | F20: =SUM(G20:R20) -> 0
B21: misc. | C21: Temp Services | F21: =SUM(G21:R21) -> 0
C22: Bank Fees | F22: =SUM(G22:R22) -> 0
C24: Flooring
C25: Paint
C26: bathroom
C27: electrical work | F27: =SUM(G27:R27) -> 0
C30: Gross Income | F30: =F3-F5 -> 21747.96

Sheet CC-21
B1: =Summary!I5 -> 2021 | F1: ="CHERRY CREST RENTAL " & B1 &" ONLY" -> CHERRY CREST RENTAL 2021 ONLY
E2: TOTAL | F2: Jan | G2: Feb | H2: Mar | I2: Apr | J2: May | K2: Jun | L2: July | M2: Aug | N2: Sep | O2: Oct | P2: Nov | Q2: Dec
B3: 1099 Revenue | E3: 26760 | F3: =$E$3/12 -> 2230 | G3: =$E$3/12 -> 2230 | H3: =$E$3/12 -> 2230 | I3: =$E$3/12 -> 2230 | J3: =$E$3/12 -> 2230 | K3: =$E$3/12 -> 2230 | L3: =$E$3/12 -> 2230 | M3: =$E$3/12 -> 2230 | ... Q3: =$E$3/12 -> 2230
B5: Total Expenses | E5: =SUM(F5:Q5) -> 5012.04 | F5: =SUM(F6:F22) -> 417.67 | G5: =SUM(G6:G22) -> 417.67 | H5: =SUM(H6:H22) -> 417.67 | I5: =SUM(I6:I22) -> 417.67 | J5: =SUM(J6:J22) -> 417.67 | K5: =SUM(K6:K22) -> 417.67 | L5: =SUM(L6:L22) -> 417.67 | M5: =SUM(M6:M22) -> 417.67 | ... Q5: =SUM(Q6:Q22) -> 417.67
B6: Mortgage Interest | E6: =SUM(F6:Q6) -> 0 | F6: 0 | G6: 0 | H6: 0 | I6: 0 | J6: 0 | K6: 0 | L6: 0 | M6: 0 | N6: 0 | O6: 0 | P6: 0 | Q6: 0
B7: Real-estate Taxes | E7: =SUM(F7:Q7) -> 0
B8: Home Owners Insurance | E8: =SUM(F8:Q8) -> 0
B9: HOA | E9: =SUM(F9:Q9) -> 5012.04 | F9: 417.67 | G9: 417.67 | H9: 417.67 | I9: 417.67 | J9: 417.67 | K9: 417.67 | L9: 417.67 | M9: 417.67 | N9: 417.67 | O9: 417.67 | P9: 417.67 | Q9: 417.67
B10: Appliance Maintenance | E10: =SUM(F10:Q10) -> 0
B11: Property Management | E11: =SUM(F11:Q11) -> 0
B13: ELECTRICITY | E13: =SUM(F13:Q13) -> 0
B14: WASTE | E14: =SUM(F14:Q14) -> 0
B15: Water & Sewer | E15: =SUM(F15:Q15) -> 0
B16: Security | E16: =SUM(F16:Q16) -> 0
A17: xfiniti | B17: BROADBAND | E17: =SUM(F17:Q17) -> 0
B19: Landscaping | E19: =SUM(F19:Q19) -> 0
B20: Supplies | E20: =SUM(F20:Q20) -> 0
A21: misc. | B21: Temp Services | E21: =SUM(F21:Q21) -> 0
B22: Bank Fees | E22: =SUM(F22:Q22) -> 0
B24: Flooring
B25: Paint
B26: bathroom
B27: electrical work | E27: =SUM(F27:Q27) -> 0
B30: Gross Income | E30: =E3-E5 -> 21747.96

Sheet CC-20
B1: =Summary!J5 -> 2020 | G1: ="CHERRY CREST RENTAL " & B1 &" ONLY" -> CHERRY CREST RENTAL 2020 ONLY
F2: TOTAL | G2: Jan | H2: Feb | I2: Mar | J2: Apr | K2: May | L2: Jun | M2: July | N2: Aug | O2: Sep | P2: Oct | Q2: Nov | R2: Dec
B3: Rental Revenue | F3: =SUM(G3:R3) -> 0
F4: YTD | G4: =G3 -> 0
B5: Total Expenses | F5: =SUM(G5:R5) -> 0
B6: Ratio of Home Use | C6: 0.17
B7: Mortgage Interest | F7: =SUM(G7:R7) -> 0
B8: ELECTRICITY | F8: =SUM(G8:R8) -> 0
B9: WASTE | F9: =SUM(G9:R9) -> 0
B10: Water | F10: =SUM(G10:R10) -> 0
B11: Security | F11: =SUM(G11:R11) -> 0
B12: Landscaping | F12: =SUM(G12:R12) -> 0
